Workbook
Name Customer_Name: OFFSET('Customer Name'!$D$2,,,COUNTIF('Customer Name'!$D:$D,"*?")-1)
Name d: OFFSET('[1]Customer Name'!$D$2,,,COUNTIF('[1]Customer Name'!$D:$D,"*?")-1)
Name Make: OFFSET(Make!$D$2,,,COUNTIF(Make!$D:$D,"*?")-1)
Name Products: OFFSET(Product!$D$2,,,COUNTIF(Product!$D:$D,"*?")-1)
Name Raw_Material: OFFSET('Raw material'!$D$2,,,COUNTIF('Raw material'!$D:$D,"*?")-1)
Name Supplier: OFFSET(Supplier!$D$2,,,COUNTIF(Supplier!$D:$D,"*?")-1)

Sheet Legend
A1: * Before editing, Latest file to be considered
A2: * Green Label Columns only Editable
A3: * Red Label Columns are not Editable
A4: * Fitting Ratio: First number indicates STRAIGHT & Second Number Indicates FITTINGS always.
A5: 70-30 ( Indicates 70% straight & 30% Fittings) same format to be used while writing
A6: Planning: If your using AMNS Make or 1250 Width Coil, Please mention make in Remarks Column (Consumption)

Sheet Purchase
K1: SUM(Rs) | N1: =SUM(N3:N1048576) -> 33293758 | O1: =SUM(O3:O1048576) -> 2915240.7 | P1: =SUM(P3:P1048576) -> 2915240.7 | Q1: =SUM(Q3:Q1048576) -> 178191.07 | R1: =SUM(R3:R1048576) -> 149916 | T1: =SUM(T3:T1048576) -> 39452347
A2: SI NO | B2: MONTH | C2: DATE | D2: PO NO | E2: PO DATE | F2: SUPPLIER | G2: MAKE | H2: INV NO | I2: IGR NO | J2: RAW MATERIAL | K2: UNIT | L2: QTY | M2: Rate | N2: BASIC | O2: CGST | P2: SGST | Q2: IGST | R2: TRANS. AS INVOICE | S2: TRANS./UNIT | T2: TOTAL
A3: =IF(C3="","",COUNT($C$3:C3)) -> 1 | B3: =IF(C3="","",TEXT(C3,"mmmm")) -> April | C3: 44652 | F3: Opening stock | G3: JSW | J3: 120gsm 26G | K3: =IF(ISNUMBER(SEARCH("gsm",J:J)),"Kg's",IF(ISNUMBER(SEARCH("Tape",J:J)),"Roll",IF(ISNUMBER(SEARCH("Thermal",J:J)),"Sqmt",IF(ISNUMBER(SEARCH("Acou",J:J)),"Sqmt",IF(ISNUMBER(SEARCH("ss",J:J)),"Kg's",IF(ISNUMBER(SEARCH("Alu",J:J)),"Kg's",IF(ISNUMBER(SEARCH("Gasket",J:J)),"Rmt",IF(ISNUMBER(SEARCH("Cleats",J:J)),"No's",IF(ISNUMBER(SEARCH("Tube",J:J)),"No's",IF(ISNUMBER(SEARCH("Bracket",J:J)),"No's",IF(ISNUMBER(SEARCH("Corner",J:J)),"No's",IF(ISNUMBER(SEARCH("MS",J:J)),"Kg's",IF(ISNUMBER(SEARCH("Bucket",J:J)),"Kg's",IF(ISNUMBER(SEARCH("stretch",J:J)),"Kg's",IF(ISNUMBER(SEARCH("Bubble",J:J)),"Roll",IF(ISNUMBER(SEARCH("JTR",J:J)),"Rmt",IF(ISNUMBER(SEARCH("Rod",J:J)),"Kg's",IF(ISNUMBER(SEARCH("Handle",J:J)),"No's",IF(ISNUMBER(SEARCH("Gear",J:J)),"No's",IF(ISNUMBER(SEARCH("Bush",J:J)),"No's","")))))))))))))))))))) -> Kg's | L3: 1835 | T3: =IF(N3="","",SUM(N3,O3,P3,Q3,R3))
A4: =IF(C4="","",COUNT($C$3:C4)) -> 2 | B4: =IF(C4="","",TEXT(C4,"mmmm")) -> April | C4: 44652 | F4: Opening stock | G4: JSW | J4: 120gsm 24G | K4: =IF(ISNUMBER(SEARCH("gsm",J:J)),"Kg's",IF(ISNUMBER(SEARCH("Tape",J:J)),"Roll",IF(ISNUMBER(SEARCH("Thermal",J:J)),"Sqmt",IF(ISNUMBER(SEARCH("Acou",J:J)),"Sqmt",IF(ISNUMBER(SEARCH("ss",J:J)),"Kg's",IF(ISNUMBER(SEARCH("Alu",J:J)),"Kg's",IF(ISNUMBER(SEARCH("Gasket",J:J)),"Rmt",IF(ISNUMBER(SEARCH("Cleats",J:J)),"No's",IF(ISNUMBER(SEARCH("Tube",J:J)),"No's",IF(ISNUMBER(SEARCH("Bracket",J:J)),"No's",IF(ISNUMBER(SEARCH("Corner",J:J)),"No's",IF(ISNUMBER(SEARCH("MS",J:J)),"Kg's",IF(ISNUMBER(SEARCH("Bucket",J:J)),"Kg's",IF(ISNUMBER(SEARCH("stretch",J:J)),"Kg's",IF(ISNUMBER(SEARCH("Bubble",J:J)),"Roll",IF(ISNUMBER(SEARCH("JTR",J:J)),"Rmt",IF(ISNUMBER(SEARCH("Rod",J:J)),"Kg's",IF(ISNUMBER(SEARCH("Handle",J:J)),"No's",IF(ISNUMBER(SEARCH("Gear",J:J)),"No's",IF(ISNUMBER(SEARCH("Bush",J:J)),"No's","")))))))))))))))))))) -> Kg's | L4: =12196+1241+1934+49.5+1412 -> 16832.5 | T4: =IF(N4="","",SUM(N4,O4,P4,Q4,R4))
A5: =IF(C5="","",COUNT($C$3:C5)) -> 3 | B5: =IF(C5="","",TEXT(C5,"mmmm")) -> April | C5: 44652 | F5: Opening stock | G5: JSW | J5: 120gsm 22G | K5: =IF(ISNUMBER(SEARCH("gsm",J:J)),"Kg's",IF(ISNUMBER(SEARCH("Tape",J:J)),"Roll",IF(ISNUMBER(SEARCH("Thermal",J:J)),"Sqmt",IF(ISNUMBER(SEARCH("Acou",J:J)),"Sqmt",IF(ISNUMBER(SEARCH("ss",J:J)),"Kg's",IF(ISNUMBER(SEARCH("Alu",J:J)),"Kg's",IF(ISNUMBER(SEARCH("Gasket",J:J)),"Rmt",IF(ISNUMBER(SEARCH("Cleats",J:J)),"No's",IF(ISNUMBER(SEARCH("Tube",J:J)),"No's",IF(ISNUMBER(SEARCH("Bracket",J:J)),"No's",IF(ISNUMBER(SEARCH("Corner",J:J)),"No's",IF(ISNUMBER(SEARCH("MS",J:J)),"Kg's",IF(ISNUMBER(SEARCH("Bucket",J:J)),"Kg's",IF(ISNUMBER(SEARCH("stretch",J:J)),"Kg's",IF(ISNUMBER(SEARCH("Bubble",J:J)),"Roll",IF(ISNUMBER(SEARCH("JTR",J:J)),"Rmt",IF(ISNUMBER(SEARCH("Rod",J:J)),"Kg's",IF(ISNUMBER(SEARCH("Handle",J:J)),"No's",IF(ISNUMBER(SEARCH("Gear",J:J)),"No's",IF(ISNUMBER(SEARCH("Bush",J:J)),"No's","")))))))))))))))))))) -> Kg's | L5: =5528+1228.4+99.2 -> 6855.6 | T5: =IF(N5="","",SUM(N5,O5,P5,Q5,R5))
A6: =IF(C6="","",COUNT($C$3:C6)) -> 4 | B6: =IF(C6="","",TEXT(C6,"mmmm")) -> April | C6: 44652 | F6: Opening stock | G6: JSW | J6: 120gsm 20G | K6: =IF(ISNUMBER(SEARCH("gsm",J:J)),"Kg's",IF(ISNUMBER(SEARCH("Tape",J:J)),"Roll",IF(ISNUMBER(SEARCH("Thermal",J:J)),"Sqmt",IF(ISNUMBER(SEARCH("Acou",J:J)),"Sqmt",IF(ISNUMBER(SEARCH("ss",J:J)),"Kg's",IF(ISNUMBER(SEARCH("Alu",J:J)),"Kg's",IF(ISNUMBER(SEARCH("Gasket",J:J)),"Rmt",IF(ISNUMBER(SEARCH("Cleats",J:J)),"No's",IF(ISNUMBER(SEARCH("Tube",J:J)),"No's",IF(ISNUMBER(SEARCH("Bracket",J:J)),"No's",IF(ISNUMBER(SEARCH("Corner",J:J)),"No's",IF(ISNUMBER(SEARCH("MS",J:J)),"Kg's",IF(ISNUMBER(SEARCH("Bucket",J:J)),"Kg's",IF(ISNUMBER(SEARCH("stretch",J:J)),"Kg's",IF(ISNUMBER(SEARCH("Bubble",J:J)),"Roll",IF(ISNUMBER(SEARCH("JTR",J:J)),"Rmt",IF(ISNUMBER(SEARCH("Rod",J:J)),"Kg's",IF(ISNUMBER(SEARCH("Handle",J:J)),"No's",IF(ISNUMBER(SEARCH("Gear",J:J)),"No's",IF(ISNUMBER(SEARCH("Bush",J:J)),"No's","")))))))))))))))))))) -> Kg's | L6: =2856+2189.9+503.2 -> 5549.1 | T6: =IF(N6="","",SUM(N6,O6,P6,Q6,R6))
A7: =IF(C7="","",COUNT($C$3:C7)) -> 5 | B7: =IF(C7="","",TEXT(C7,"mmmm")) -> April | C7: 44652 | F7: Opening stock | G7: JSW | J7: 120gsm 18G | K7: =IF(ISNUMBER(SEARCH("gsm",J:J)),"Kg's",IF(ISNUMBER(SEARCH("Tape",J:J)),"Roll",IF(ISNUMBER(SEARCH("Thermal",J:J)),"Sqmt",IF(ISNUMBER(SEARCH("Acou",J:J)),"Sqmt",IF(ISNUMBER(SEARCH("ss",J:J)),"Kg's",IF(ISNUMBER(SEARCH("Alu",J:J)),"Kg's",IF(ISNUMBER(SEARCH("Gasket",J:J)),"Rmt",IF(ISNUMBER(SEARCH("Cleats",J:J)),"No's",IF(ISNUMBER(SEARCH("Tube",J:J)),"No's",IF(ISNUMBER(SEARCH("Bracket",J:J)),"No's",IF(ISNUMBER(SEARCH("Corner",J:J)),"No's",IF(ISNUMBER(SEARCH("MS",J:J)),"Kg's",IF(ISNUMBER(SEARCH("Bucket",J:J)),"Kg's",IF(ISNUMBER(SEARCH("stretch",J:J)),"Kg's",IF(ISNUMBER(SEARCH("Bubble",J:J)),"Roll",IF(ISNUMBER(SEARCH("JTR",J:J)),"Rmt",IF(ISNUMBER(SEARCH("Rod",J:J)),"Kg's",IF(ISNUMBER(SEARCH("Handle",J:J)),"No's",IF(ISNUMBER(SEARCH("Gear",J:J)),"No's",IF(ISNUMBER(SEARCH("Bush",J:J)),"No's","")))))))))))))))))))) -> Kg's | L7: 6453 | T7: =IF(N7="","",SUM(N7,O7,P7,Q7,R7))
A8: =IF(C8="","",COUNT($C$3:C8)) -> 6 | B8: =IF(C8="","",TEXT(C8,"mmmm")) -> April | C8: 44652 | F8: Opening stock | G8: JSW | J8: 120gsm Slit 26G | K8: =IF(ISNUMBER(SEARCH("gsm",J:J)),"Kg's",IF(ISNUMBER(SEARCH("Tape",J:J)),"Roll",IF(ISNUMBER(SEARCH("Thermal",J:J)),"Sqmt",IF(ISNUMBER(SEARCH("Acou",J:J)),"Sqmt",IF(ISNUMBER(SEARCH("ss",J:J)),"Kg's",IF(ISNUMBER(SEARCH("Alu",J:J)),"Kg's",IF(ISNUMBER(SEARCH("Gasket",J:J)),"Rmt",IF(ISNUMBER(SEARCH("Cleats",J:J)),"No's",IF(ISNUMBER(SEARCH("Tube",J:J)),"No's",IF(ISNUMBER(SEARCH("Bracket",J:J)),"No's",IF(ISNUMBER(SEARCH("Corner",J:J)),"No's",IF(ISNUMBER(SEARCH("MS",J:J)),"Kg's",IF(ISNUMBER(SEARCH("Bucket",J:J)),"Kg's",IF(ISNUMBER(SEARCH("stretch",J:J)),"Kg's",IF(ISNUMBER(SEARCH("Bubble",J:J)),"Roll",IF(ISNUMBER(SEARCH("JTR",J:J)),"Rmt",IF(ISNUMBER(SEARCH("Rod",J:J)),"Kg's",IF(ISNUMBER(SEARCH("Handle",J:J)),"No's",IF(ISNUMBER(SEARCH("Gear",J:J)),"No's",IF(ISNUMBER(SEARCH("Bush",J:J)),"No's","")))))))))))))))))))) -> Kg's | L8: 2970 | T8: =IF(N8="","",SUM(N8,O8,P8,Q8,R8))
A9: =IF(C9="","",COUNT($C$3:C9)) -> 7 | B9: =IF(C9="","",TEXT(C9,"mmmm")) -> April | C9: 44652 | F9: Opening stock | G9: JSW | J9: 120gsm Slit 24G | K9: =IF(ISNUMBER(SEARCH("gsm",J:J)),"Kg's",IF(ISNUMBER(SEARCH("Tape",J:J)),"Roll",IF(ISNUMBER(SEARCH("Thermal",J:J)),"Sqmt",IF(ISNUMBER(SEARCH("Acou",J:J)),"Sqmt",IF(ISNUMBER(SEARCH("ss",J:J)),"Kg's",IF(ISNUMBER(SEARCH("Alu",J:J)),"Kg's",IF(ISNUMBER(SEARCH("Gasket",J:J)),"Rmt",IF(ISNUMBER(SEARCH("Cleats",J:J)),"No's",IF(ISNUMBER(SEARCH("Tube",J:J)),"No's",IF(ISNUMBER(SEARCH("Bracket",J:J)),"No's",IF(ISNUMBER(SEARCH("Corner",J:J)),"No's",IF(ISNUMBER(SEARCH("MS",J:J)),"Kg's",IF(ISNUMBER(SEARCH("Bucket",J:J)),"Kg's",IF(ISNUMBER(SEARCH("stretch",J:J)),"Kg's",IF(ISNUMBER(SEARCH("Bubble",J:J)),"Roll",IF(ISNUMBER(SEARCH("JTR",J:J)),"Rmt",IF(ISNUMBER(SEARCH("Rod",J:J)),"Kg's",IF(ISNUMBER(SEARCH("Handle",J:J)),"No's",IF(ISNUMBER(SEARCH("Gear",J:J)),"No's",IF(ISNUMBER(SEARCH("Bush",J:J)),"No's","")))))))))))))))))))) -> Kg's | L9: =13279+3307.6 -> 16586.6 | T9: =IF(N9="","",SUM(N9,O9,P9,Q9,R9))
A10: =IF(C10="","",COUNT($C$3:C10)) -> 8 | B10: =IF(C10="","",TEXT(C10,"mmmm")) -> April | C10: 44652 | F10: Opening stock | G10: JSW | J10: 120gsm Slit 22G | K10: =IF(ISNUMBER(SEARCH("gsm",J:J)),"Kg's",IF(ISNUMBER(SEARCH("Tape",J:J)),"Roll",IF(ISNUMBER(SEARCH("Thermal",J:J)),"Sqmt",IF(ISNUMBER(SEARCH("Acou",J:J)),"Sqmt",IF(ISNUMBER(SEARCH("ss",J:J)),"Kg's",IF(ISNUMBER(SEARCH("Alu",J:J)),"Kg's",IF(ISNUMBER(SEARCH("Gasket",J:J)),"Rmt",IF(ISNUMBER(SEARCH("Cleats",J:J)),"No's",IF(ISNUMBER(SEARCH("Tube",J:J)),"No's",IF(ISNUMBER(SEARCH("Bracket",J:J)),"No's",IF(ISNUMBER(SEARCH("Corner",J:J)),"No's",IF(ISNUMBER(SEARCH("MS",J:J)),"Kg's",IF(ISNUMBER(SEARCH("Bucket",J:J)),"Kg's",IF(ISNUMBER(SEARCH("stretch",J:J)),"Kg's",IF(ISNUMBER(SEARCH("Bubble",J:J)),"Roll",IF(ISNUMBER(SEARCH("JTR",J:J)),"Rmt",IF(ISNUMBER(SEARCH("Rod",J:J)),"Kg's",IF(ISNUMBER(SEARCH("Handle",J:J)),"No's",IF(ISNUMBER(SEARCH("Gear",J:J)),"No's",IF(ISNUMBER(SEARCH("Bush",J:J)),"No's","")))))))))))))))))))) -> Kg's | L10: =22155.4+5516.4+26.4 -> 27698.2 | T10: =IF(N10="","",SUM(N10,O10,P10,Q10,R10))
A11: =IF(C11="","",COUNT($C$3:C11)) -> 9 | B11: =IF(C11="","",TEXT(C11,"mmmm")) -> April | C11: 44652 | F11: Opening stock | G11: JSW | J11: 120gsm Slit 20G | K11: =IF(ISNUMBER(SEARCH("gsm",J:J)),"Kg's",IF(ISNUMBER(SEARCH("Tape",J:J)),"Roll",IF(ISNUMBER(SEARCH("Thermal",J:J)),"Sqmt",IF(ISNUMBER(SEARCH("Acou",J:J)),"Sqmt",IF(ISNUMBER(SEARCH("ss",J:J)),"Kg's",IF(ISNUMBER(SEARCH("Alu",J:J)),"Kg's",IF(ISNUMBER(SEARCH("Gasket",J:J)),"Rmt",IF(ISNUMBER(SEARCH("Cleats",J:J)),"No's",IF(ISNUMBER(SEARCH("Tube",J:J)),"No's",IF(ISNUMBER(SEARCH("Bracket",J:J)),"No's",IF(ISNUMBER(SEARCH("Corner",J:J)),"No's",IF(ISNUMBER(SEARCH("MS",J:J)),"Kg's",IF(ISNUMBER(SEARCH("Bucket",J:J)),"Kg's",IF(ISNUMBER(SEARCH("stretch",J:J)),"Kg's",IF(ISNUMBER(SEARCH("Bubble",J:J)),"Roll",IF(ISNUMBER(SEARCH("JTR",J:J)),"Rmt",IF(ISNUMBER(SEARCH("Rod",J:J)),"Kg's",IF(ISNUMBER(SEARCH("Handle",J:J)),"No's",IF(ISNUMBER(SEARCH("Gear",J:J)),"No's",IF(ISNUMBER(SEARCH("Bush",J:J)),"No's","")))))))))))))))))))) -> Kg's | L11: =1848+5655.5 -> 7503.5 | T11: =IF(N11="","",SUM(N11,O11,P11,Q11,R11))
A12: =IF(C12="","",COUNT($C$3:C12)) -> 10 | B12: =IF(C12="","",TEXT(C12,"mmmm")) -> April | C12: 44652 | F12: Opening stock | G12: JSW | J12: 120gsm Slit 18G | K12: =IF(ISNUMBER(SEARCH("gsm",J:J)),"Kg's",IF(ISNUMBER(SEARCH("Tape",J:J)),"Roll",IF(ISNUMBER(SEARCH("Thermal",J:J)),"Sqmt",IF(ISNUMBER(SEARCH("Acou",J:J)),"Sqmt",IF(ISNUMBER(SEARCH("ss",J:J)),"Kg's",IF(ISNUMBER(SEARCH("Alu",J:J)),"Kg's",IF(ISNUMBER(SEARCH("Gasket",J:J)),"Rmt",IF(ISNUMBER(SEARCH("Cleats",J:J)),"No's",IF(ISNUMBER(SEARCH("Tube",J:J)),"No's",IF(ISNUMBER(SEARCH("Bracket",J:J)),"No's",IF(ISNUMBER(SEARCH("Corner",J:J)),"No's",IF(ISNUMBER(SEARCH("MS",J:J)),"Kg's",IF(ISNUMBER(SEARCH("Bucket",J:J)),"Kg's",IF(ISNUMBER(SEARCH("stretch",J:J)),"Kg's",IF(ISNUMBER(SEARCH("Bubble",J:J)),"Roll",IF(ISNUMBER(SEARCH("JTR",J:J)),"Rmt",IF(ISNUMBER(SEARCH("Rod",J:J)),"Kg's",IF(ISNUMBER(SEARCH("Handle",J:J)),"No's",IF(ISNUMBER(SEARCH("Gear",J:J)),"No's",IF(ISNUMBER(SEARCH("Bush",J:J)),"No's","")))))))))))))))))))) -> Kg's | L12: =872+775.6+302.2 -> 1949.8 | T12: =IF(N12="","",SUM(N12,O12,P12,Q12,R12))
A13: =IF(C13="","",COUNT($C$3:C13)) -> 11 | B13: =IF(C13="","",TEXT(C13,"mmmm")) -> April | C13: 44652 | F13: Opening stock | G13: JSW | J13: 275gsm 24G | K13: =IF(ISNUMBER(SEARCH("gsm",J:J)),"Kg's",IF(ISNUMBER(SEARCH("Tape",J:J)),"Roll",IF(ISNUMBER(SEARCH("Thermal",J:J)),"Sqmt",IF(ISNUMBER(SEARCH("Acou",J:J)),"Sqmt",IF(ISNUMBER(SEARCH("ss",J:J)),"Kg's",IF(ISNUMBER(SEARCH("Alu",J:J)),"Kg's",IF(ISNUMBER(SEARCH("Gasket",J:J)),"Rmt",IF(ISNUMBER(SEARCH("Cleats",J:J)),"No's",IF(ISNUMBER(SEARCH("Tube",J:J)),"No's",IF(ISNUMBER(SEARCH("Bracket",J:J)),"No's",IF(ISNUMBER(SEARCH("Corner",J:J)),"No's",IF(ISNUMBER(SEARCH("MS",J:J)),"Kg's",IF(ISNUMBER(SEARCH("Bucket",J:J)),"Kg's",IF(ISNUMBER(SEARCH("stretch",J:J)),"Kg's",IF(ISNUMBER(SEARCH("Bubble",J:J)),"Roll",IF(ISNUMBER(SEARCH("JTR",J:J)),"Rmt",IF(ISNUMBER(SEARCH("Rod",J:J)),"Kg's",IF(ISNUMBER(SEARCH("Handle",J:J)),"No's",IF(ISNUMBER(SEARCH("Gear",J:J)),"No's",IF(ISNUMBER(SEARCH("Bush",J:J)),"No's","")))))))))))))))))))) -> Kg's | L13: 4183
A14: =IF(C14="","",COUNT($C$3:C14)) -> 12 | B14: =IF(C14="","",TEXT(C14,"mmmm")) -> April | C14: 44652 | F14: Opening stock | G14: JSW | J14: 275gsm 22G | K14: =IF(ISNUMBER(SEARCH("gsm",J:J)),"Kg's",IF(ISNUMBER(SEARCH("Tape",J:J)),"Roll",IF(ISNUMBER(SEARCH("Thermal",J:J)),"Sqmt",IF(ISNUMBER(SEARCH("Acou",J:J)),"Sqmt",IF(ISNUMBER(SEARCH("ss",J:J)),"Kg's",IF(ISNUMBER(SEARCH("Alu",J:J)),"Kg's",IF(ISNUMBER(SEARCH("Gasket",J:J)),"Rmt",IF(ISNUMBER(SEARCH("Cleats",J:J)),"No's",IF(ISNUMBER(SEARCH("Tube",J:J)),"No's",IF(ISNUMBER(SEARCH("Bracket",J:J)),"No's",IF(ISNUMBER(SEARCH("Corner",J:J)),"No's",IF(ISNUMBER(SEARCH("MS",J:J)),"Kg's",IF(ISNUMBER(SEARCH("Bucket",J:J)),"Kg's",IF(ISNUMBER(SEARCH("stretch",J:J)),"Kg's",IF(ISNUMBER(SEARCH("Bubble",J:J)),"Roll",IF(ISNUMBER(SEARCH("JTR",J:J)),"Rmt",IF(ISNUMBER(SEARCH("Rod",J:J)),"Kg's",IF(ISNUMBER(SEARCH("Handle",J:J)),"No's",IF(ISNUMBER(SEARCH("Gear",J:J)),"No's",IF(ISNUMBER(SEARCH("Bush",J:J)),"No's","")))))))))))))))))))) -> Kg's | L14: =9225+1381.4 -> 10606.4 | T14: =IF(N14="","",SUM(N14,O14,P14,Q14,R14))
A15: =IF(C15="","",COUNT($C$3:C15)) -> 13 | B15: =IF(C15="","",TEXT(C15,"mmmm")) -> April | C15: 44652 | F15: Opening stock | G15: JSW | J15: 275gsm 20G | K15: =IF(ISNUMBER(SEARCH("gsm",J:J)),"Kg's",IF(ISNUMBER(SEARCH("Tape",J:J)),"Roll",IF(ISNUMBER(SEARCH("Thermal",J:J)),"Sqmt",IF(ISNUMBER(SEARCH("Acou",J:J)),"Sqmt",IF(ISNUMBER(SEARCH("ss",J:J)),"Kg's",IF(ISNUMBER(SEARCH("Alu",J:J)),"Kg's",IF(ISNUMBER(SEARCH("Gasket",J:J)),"Rmt",IF(ISNUMBER(SEARCH("Cleats",J:J)),"No's",IF(ISNUMBER(SEARCH("Tube",J:J)),"No's",IF(ISNUMBER(SEARCH("Bracket",J:J)),"No's",IF(ISNUMBER(SEARCH("Corner",J:J)),"No's",IF(ISNUMBER(SEARCH("MS",J:J)),"Kg's",IF(ISNUMBER(SEARCH("Bucket",J:J)),"Kg's",IF(ISNUMBER(SEARCH("stretch",J:J)),"Kg's",IF(ISNUMBER(SEARCH("Bubble",J:J)),"Roll",IF(ISNUMBER(SEARCH("JTR",J:J)),"Rmt",IF(ISNUMBER(SEARCH("Rod",J:J)),"Kg's",IF(ISNUMBER(SEARCH("Handle",J:J)),"No's",IF(ISNUMBER(SEARCH("Gear",J:J)),"No's",IF(ISNUMBER(SEARCH("Bush",J:J)),"No's","")))))))))))))))))))) -> Kg's | L15: 299 | T15: =IF(N15="","",SUM(N15,O15,P15,Q15,R15))
A16: =IF(C16="","",COUNT($C$3:C16)) -> 14 | B16: =IF(C16="","",TEXT(C16,"mmmm")) -> April | C16: 44652 | F16: Opening stock | G16: JSW | J16: 275gsm 18G | K16: =IF(ISNUMBER(SEARCH("gsm",J:J)),"Kg's",IF(ISNUMBER(SEARCH("Tape",J:J)),"Roll",IF(ISNUMBER(SEARCH("Thermal",J:J)),"Sqmt",IF(ISNUMBER(SEARCH("Acou",J:J)),"Sqmt",IF(ISNUMBER(SEARCH("ss",J:J)),"Kg's",IF(ISNUMBER(SEARCH("Alu",J:J)),"Kg's",IF(ISNUMBER(SEARCH("Gasket",J:J)),"Rmt",IF(ISNUMBER(SEARCH("Cleats",J:J)),"No's",IF(ISNUMBER(SEARCH("Tube",J:J)),"No's",IF(ISNUMBER(SEARCH("Bracket",J:J)),"No's",IF(ISNUMBER(SEARCH("Corner",J:J)),"No's",IF(ISNUMBER(SEARCH("MS",J:J)),"Kg's",IF(ISNUMBER(SEARCH("Bucket",J:J)),"Kg's",IF(ISNUMBER(SEARCH("stretch",J:J)),"Kg's",IF(ISNUMBER(SEARCH("Bubble",J:J)),"Roll",IF(ISNUMBER(SEARCH("JTR",J:J)),"Rmt",IF(ISNUMBER(SEARCH("Rod",J:J)),"Kg's",IF(ISNUMBER(SEARCH("Handle",J:J)),"No's",IF(ISNUMBER(SEARCH("Gear",J:J)),"No's",IF(ISNUMBER(SEARCH("Bush",J:J)),"No's","")))))))))))))))))))) -> Kg's | L16: 1251 | T16: =IF(N16="","",SUM(N16,O16,P16,Q16,R16))
A17: =IF(C17="","",COUNT($C$3:C17)) -> 15 | B17: =IF(C17="","",TEXT(C17,"mmmm")) -> April | C17: 44652 | F17: Opening stock | G17: JSW | J17: 275gsm 16G | K17: =IF(ISNUMBER(SEARCH("gsm",J:J)),"Kg's",IF(ISNUMBER(SEARCH("Tape",J:J)),"Roll",IF(ISNUMBER(SEARCH("Thermal",J:J)),"Sqmt",IF(ISNUMBER(SEARCH("Acou",J:J)),"Sqmt",IF(ISNUMBER(SEARCH("ss",J:J)),"Kg's",IF(ISNUMBER(SEARCH("Alu",J:J)),"Kg's",IF(ISNUMBER(SEARCH("Gasket",J:J)),"Rmt",IF(ISNUMBER(SEARCH("Cleats",J:J)),"No's",IF(ISNUMBER(SEARCH("Tube",J:J)),"No's",IF(ISNUMBER(SEARCH("Bracket",J:J)),"No's",IF(ISNUMBER(SEARCH("Corner",J:J)),"No's",IF(ISNUMBER(SEARCH("MS",J:J)),"Kg's",IF(ISNUMBER(SEARCH("Bucket",J:J)),"Kg's",IF(ISNUMBER(SEARCH("stretch",J:J)),"Kg's",IF(ISNUMBER(SEARCH("Bubble",J:J)),"Roll",IF(ISNUMBER(SEARCH("JTR",J:J)),"Rmt",IF(ISNUMBER(SEARCH("Rod",J:J)),"Kg's",IF(ISNUMBER(SEARCH("Handle",J:J)),"No's",IF(ISNUMBER(SEARCH("Gear",J:J)),"No's",IF(ISNUMBER(SEARCH("Bush",J:J)),"No's","")))))))))))))))))))) -> Kg's | L17: 5919 | T17: =IF(N17="","",SUM(N17,O17,P17,Q17,R17))
A18: =IF(C18="","",COUNT($C$3:C18)) -> 16 | B18: =IF(C18="","",TEXT(C18,"mmmm")) -> April | C18: 44652 | F18: Opening stock | G18: JSW | J18: Alu. 1mm | K18: =IF(ISNUMBER(SEARCH("gsm",J:J)),"Kg's",IF(ISNUMBER(SEARCH("Tape",J:J)),"Roll",IF(ISNUMBER(SEARCH("Thermal",J:J)),"Sqmt",IF(ISNUMBER(SEARCH("Acou",J:J)),"Sqmt",IF(ISNUMBER(SEARCH("ss",J:J)),"Kg's",IF(ISNUMBER(SEARCH("Alu",J:J)),"Kg's",IF(ISNUMBER(SEARCH("Gasket",J:J)),"Rmt",IF(ISNUMBER(SEARCH("Cleats",J:J)),"No's",IF(ISNUMBER(SEARCH("Tube",J:J)),"No's",IF(ISNUMBER(SEARCH("Bracket",J:J)),"No's",IF(ISNUMBER(SEARCH("Corner",J:J)),"No's",IF(ISNUMBER(SEARCH("MS",J:J)),"Kg's",IF(ISNUMBER(SEARCH("Bucket",J:J)),"Kg's",IF(ISNUMBER(SEARCH("stretch",J:J)),"Kg's",IF(ISNUMBER(SEARCH("Bubble",J:J)),"Roll",IF(ISNUMBER(SEARCH("JTR",J:J)),"Rmt",IF(ISNUMBER(SEARCH("Rod",J:J)),"Kg's",IF(ISNUMBER(SEARCH("Handle",J:J)),"No's",IF(ISNUMBER(SEARCH("Gear",J:J)),"No's",IF(ISNUMBER(SEARCH("Bush",J:J)),"No's","")))))))))))))))))))) -> Kg's | L18: 170 | T18: =IF(N18="","",SUM(N18,O18,P18,Q18,R18))
A19: =IF(C19="","",COUNT($C$3:C19)) -> 17 | B19: =IF(C19="","",TEXT(C19,"mmmm")) -> April | C19: 44652 | F19: Opening stock | G19: JSW | J19: Alu. 0.8mm | K19: =IF(ISNUMBER(SEARCH("gsm",J:J)),"Kg's",IF(ISNUMBER(SEARCH("Tape",J:J)),"Roll",IF(ISNUMBER(SEARCH("Thermal",J:J)),"Sqmt",IF(ISNUMBER(SEARCH("Acou",J:J)),"Sqmt",IF(ISNUMBER(SEARCH("ss",J:J)),"Kg's",IF(ISNUMBER(SEARCH("Alu",J:J)),"Kg's",IF(ISNUMBER(SEARCH("Gasket",J:J)),"Rmt",IF(ISNUMBER(SEARCH("Cleats",J:J)),"No's",IF(ISNUMBER(SEARCH("Tube",J:J)),"No's",IF(ISNUMBER(SEARCH("Bracket",J:J)),"No's",IF(ISNUMBER(SEARCH("Corner",J:J)),"No's",IF(ISNUMBER(SEARCH("MS",J:J)),"Kg's",IF(ISNUMBER(SEARCH("Bucket",J:J)),"Kg's",IF(ISNUMBER(SEARCH("stretch",J:J)),"Kg's",IF(ISNUMBER(SEARCH("Bubble",J:J)),"Roll",IF(ISNUMBER(SEARCH("JTR",J:J)),"Rmt",IF(ISNUMBER(SEARCH("Rod",J:J)),"Kg's",IF(ISNUMBER(SEARCH("Handle",J:J)),"No's",IF(ISNUMBER(SEARCH("Gear",J:J)),"No's",IF(ISNUMBER(SEARCH("Bush",J:J)),"No's","")))))))))))))))))))) -> Kg's | L19: 33 | T19: =IF(N19="","",SUM(N19,O19,P19,Q19,R19))
A20: =IF(C20="","",COUNT($C$3:C20)) -> 18 | B20: =IF(C20="","",TEXT(C20,"mmmm")) -> April | C20: 44652 | F20: Opening stock | J20: Corner 32mm | K20: =IF(ISNUMBER(SEARCH("gsm",J:J)),"Kg's",IF(ISNUMBER(SEARCH("Tape",J:J)),"Roll",IF(ISNUMBER(SEARCH("Thermal",J:J)),"Sqmt",IF(ISNUMBER(SEARCH("Acou",J:J)),"Sqmt",IF(ISNUMBER(SEARCH("ss",J:J)),"Kg's",IF(ISNUMBER(SEARCH("Alu",J:J)),"Kg's",IF(ISNUMBER(SEARCH("Gasket",J:J)),"Rmt",IF(ISNUMBER(SEARCH("Cleats",J:J)),"No's",IF(ISNUMBER(SEARCH("Tube",J:J)),"No's",IF(ISNUMBER(SEARCH("Bracket",J:J)),"No's",IF(ISNUMBER(SEARCH("Corner",J:J)),"No's",IF(ISNUMBER(SEARCH("MS",J:J)),"Kg's",IF(ISNUMBER(SEARCH("Bucket",J:J)),"Kg's",IF(ISNUMBER(SEARCH("stretch",J:J)),"Kg's",IF(ISNUMBER(SEARCH("Bubble",J:J)),"Roll",IF(ISNUMBER(SEARCH("JTR",J:J)),"Rmt",IF(ISNUMBER(SEARCH("Rod",J:J)),"Kg's",IF(ISNUMBER(SEARCH("Handle",J:J)),"No's",IF(ISNUMBER(SEARCH("Gear",J:J)),"No's",IF(ISNUMBER(SEARCH("Bush",J:J)),"No's","")))))))))))))))))))) -> No's | L20: 59500 | T20: =IF(N20="","",SUM(N20,O20,P20,Q20,R20))
A21: =IF(C21="","",COUNT($C$3:C21)) -> 19 | B21: =IF(C21="","",TEXT(C21,"mmmm")) -> April | C21: 44652 | F21: Opening stock | J21: Corner 25mm | K21: =IF(ISNUMBER(SEARCH("gsm",J:J)),"Kg's",IF(ISNUMBER(SEARCH("Tape",J:J)),"Roll",IF(ISNUMBER(SEARCH("Thermal",J:J)),"Sqmt",IF(ISNUMBER(SEARCH("Acou",J:J)),"Sqmt",IF(ISNUMBER(SEARCH("ss",J:J)),"Kg's",IF(ISNUMBER(SEARCH("Alu",J:J)),"Kg's",IF(ISNUMBER(SEARCH("Gasket",J:J)),"Rmt",IF(ISNUMBER(SEARCH("Cleats",J:J)),"No's",IF(ISNUMBER(SEARCH("Tube",J:J)),"No's",IF(ISNUMBER(SEARCH("Bracket",J:J)),"No's",IF(ISNUMBER(SEARCH("Corner",J:J)),"No's",IF(ISNUMBER(SEARCH("MS",J:J)),"Kg's",IF(ISNUMBER(SEARCH("Bucket",J:J)),"Kg's",IF(ISNUMBER(SEARCH("stretch",J:J)),"Kg's",IF(ISNUMBER(SEARCH("Bubble",J:J)),"Roll",IF(ISNUMBER(SEARCH("JTR",J:J)),"Rmt",IF(ISNUMBER(SEARCH("Rod",J:J)),"Kg's",IF(ISNUMBER(SEARCH("Handle",J:J)),"No's",IF(ISNUMBER(SEARCH("Gear",J:J)),"No's",IF(ISNUMBER(SEARCH("Bush",J:J)),"No's","")))))))))))))))))))) -> No's | L21: 10000 | T21: =IF(N21="","",SUM(N21,O21,P21,Q21,R21))
A22: =IF(C22="","",COUNT($C$3:C22)) -> 20 | B22: =IF(C22="","",TEXT(C22,"mmmm")) -> April | C22: 44652 | F22: Opening stock | J22: XLPE Gasket | K22: =IF(ISNUMBER(SEARCH("gsm",J:J)),"Kg's",IF(ISNUMBER(SEARCH("Tape",J:J)),"Roll",IF(ISNUMBER(SEARCH("Thermal",J:J)),"Sqmt",IF(ISNUMBER(SEARCH("Acou",J:J)),"Sqmt",IF(ISNUMBER(SEARCH("ss",J:J)),"Kg's",IF(ISNUMBER(SEARCH("Alu",J:J)),"Kg's",IF(ISNUMBER(SEARCH("Gasket",J:J)),"Rmt",IF(ISNUMBER(SEARCH("Cleats",J:J)),"No's",IF(ISNUMBER(SEARCH("Tube",J:J)),"No's",IF(ISNUMBER(SEARCH("Bracket",J:J)),"No's",IF(ISNUMBER(SEARCH("Corner",J:J)),"No's",IF(ISNUMBER(SEARCH("MS",J:J)),"Kg's",IF(ISNUMBER(SEARCH("Bucket",J:J)),"Kg's",IF(ISNUMBER(SEARCH("stretch",J:J)),"Kg's",IF(ISNUMBER(SEARCH("Bubble",J:J)),"Roll",IF(ISNUMBER(SEARCH("JTR",J:J)),"Rmt",IF(ISNUMBER(SEARCH("Rod",J:J)),"Kg's",IF(ISNUMBER(SEARCH("Handle",J:J)),"No's",IF(ISNUMBER(SEARCH("Gear",J:J)),"No's",IF(ISNUMBER(SEARCH("Bush",J:J)),"No's","")))))))))))))))))))) -> Rmt | L22: 30210 | T22: =IF(N22="","",SUM(N22,O22,P22,Q22,R22))
A23: =IF(C23="","",COUNT($C$3:C23)) -> 21 | B23: =IF(C23="","",TEXT(C23,"mmmm")) -> April | C23: 44652 | F23: Opening stock | G23: Urja | J23: Sealant Tube | K23: =IF(ISNUMBER(SEARCH("gsm",J:J)),"Kg's",IF(ISNUMBER(SEARCH("Tape",J:J)),"Roll",IF(ISNUMBER(SEARCH("Thermal",J:J)),"Sqmt",IF(ISNUMBER(SEARCH("Acou",J:J)),"Sqmt",IF(ISNUMBER(SEARCH("ss",J:J)),"Kg's",IF(ISNUMBER(SEARCH("Alu",J:J)),"Kg's",IF(ISNUMBER(SEARCH("Gasket",J:J)),"Rmt",IF(ISNUMBER(SEARCH("Cleats",J:J)),"No's",IF(ISNUMBER(SEARCH("Tube",J:J)),"No's",IF(ISNUMBER(SEARCH("Bracket",J:J)),"No's",IF(ISNUMBER(SEARCH("Corner",J:J)),"No's",IF(ISNUMBER(SEARCH("MS",J:J)),"Kg's",IF(ISNUMBER(SEARCH("Bucket",J:J)),"Kg's",IF(ISNUMBER(SEARCH("stretch",J:J)),"Kg's",IF(ISNUMBER(SEARCH("Bubble",J:J)),"Roll",IF(ISNUMBER(SEARCH("JTR",J:J)),"Rmt",IF(ISNUMBER(SEARCH("Rod",J:J)),"Kg's",IF(ISNUMBER(SEARCH("Handle",J:J)),"No's",IF(ISNUMBER(SEARCH("Gear",J:J)),"No's",IF(ISNUMBER(SEARCH("Bush",J:J)),"No's","")))))))))))))))))))) -> No's | L23: 357 | T23: =IF(N23="","",SUM(N23,O23,P23,Q23,R23))
A24: =IF(C24="","",COUNT($C$3:C24)) -> 22 | B24: =IF(C24="","",TEXT(C24,"mmmm")) -> April | C24: 44652 | F24: Opening stock | G24: Urja | J24: Sealant Bucket | K24: =IF(ISNUMBER(SEARCH("gsm",J:J)),"Kg's",IF(ISNUMBER(SEARCH("Tape",J:J)),"Roll",IF(ISNUMBER(SEARCH("Thermal",J:J)),"Sqmt",IF(ISNUMBER(SEARCH("Acou",J:J)),"Sqmt",IF(ISNUMBER(SEARCH("ss",J:J)),"Kg's",IF(ISNUMBER(SEARCH("Alu",J:J)),"Kg's",IF(ISNUMBER(SEARCH("Gasket",J:J)),"Rmt",IF(ISNUMBER(SEARCH("Cleats",J:J)),"No's",IF(ISNUMBER(SEARCH("Tube",J:J)),"No's",IF(ISNUMBER(SEARCH("Bracket",J:J)),"No's",IF(ISNUMBER(SEARCH("Corner",J:J)),"No's",IF(ISNUMBER(SEARCH("MS",J:J)),"Kg's",IF(ISNUMBER(SEARCH("Bucket",J:J)),"Kg's",IF(ISNUMBER(SEARCH("stretch",J:J)),"Kg's",IF(ISNUMBER(SEARCH("Bubble",J:J)),"Roll",IF(ISNUMBER(SEARCH("JTR",J:J)),"Rmt",IF(ISNUMBER(SEARCH("Rod",J:J)),"Kg's",IF(ISNUMBER(SEARCH("Handle",J:J)),"No's",IF(ISNUMBER(SEARCH("Gear",J:J)),"No's",IF(ISNUMBER(SEARCH("Bush",J:J)),"No's","")))))))))))))))))))) -> Kg's | L24: 100 | T24: =IF(N24="","",SUM(N24,O24,P24,Q24,R24))
A25: =IF(C25="","",COUNT($C$3:C25)) -> 23 | B25: =IF(C25="","",TEXT(C25,"mmmm")) -> December | C25: 44926 | F25: Opening stock | G25: K Flex | J25: Insu Kflex Thermal 6mm | K25: =IF(ISNUMBER(SEARCH("gsm",J:J)),"Kg's",IF(ISNUMBER(SEARCH("Tape",J:J)),"Roll",IF(ISNUMBER(SEARCH("Thermal",J:J)),"Sqmt",IF(ISNUMBER(SEARCH("Acou",J:J)),"Sqmt",IF(ISNUMBER(SEARCH("ss",J:J)),"Kg's",IF(ISNUMBER(SEARCH("Alu",J:J)),"Kg's",IF(ISNUMBER(SEARCH("Gasket",J:J)),"Rmt",IF(ISNUMBER(SEARCH("Cleats",J:J)),"No's",IF(ISNUMBER(SEARCH("Tube",J:J)),"No's",IF(ISNUMBER(SEARCH("Bracket",J:J)),"No's",IF(ISNUMBER(SEARCH("Corner",J:J)),"No's",IF(ISNUMBER(SEARCH("MS",J:J)),"Kg's",IF(ISNUMBER(SEARCH("Bucket",J:J)),"Kg's",IF(ISNUMBER(SEARCH("stretch",J:J)),"Kg's",IF(ISNUMBER(SEARCH("Bubble",J:J)),"Roll",IF(ISNUMBER(SEARCH("JTR",J:J)),"Rmt",IF(ISNUMBER(SEARCH("Rod",J:J)),"Kg's",IF(ISNUMBER(SEARCH("Handle",J:J)),"No's",IF(ISNUMBER(SEARCH("Gear",J:J)),"No's",IF(ISNUMBER(SEARCH("Bush",J:J)),"No's","")))))))))))))))))))) -> Sqmt | L25: 396
A26: =IF(C26="","",COUNT($C$3:C26)) -> 24 | B26: =IF(C26="","",TEXT(C26,"mmmm")) -> December | C26: 44926 | F26: Opening stock | G26: K Flex | J26: Insu Kflex Thermal 9mm | K26: =IF(ISNUMBER(SEARCH("gsm",J:J)),"Kg's",IF(ISNUMBER(SEARCH("Tape",J:J)),"Roll",IF(ISNUMBER(SEARCH("Thermal",J:J)),"Sqmt",IF(ISNUMBER(SEARCH("Acou",J:J)),"Sqmt",IF(ISNUMBER(SEARCH("ss",J:J)),"Kg's",IF(ISNUMBER(SEARCH("Alu",J:J)),"Kg's",IF(ISNUMBER(SEARCH("Gasket",J:J)),"Rmt",IF(ISNUMBER(SEARCH("Cleats",J:J)),"No's",IF(ISNUMBER(SEARCH("Tube",J:J)),"No's",IF(ISNUMBER(SEARCH("Bracket",J:J)),"No's",IF(ISNUMBER(SEARCH("Corner",J:J)),"No's",IF(ISNUMBER(SEARCH("MS",J:J)),"Kg's",IF(ISNUMBER(SEARCH("Bucket",J:J)),"Kg's",IF(ISNUMBER(SEARCH("stretch",J:J)),"Kg's",IF(ISNUMBER(SEARCH("Bubble",J:J)),"Roll",IF(ISNUMBER(SEARCH("JTR",J:J)),"Rmt",IF(ISNUMBER(SEARCH("Rod",J:J)),"Kg's",IF(ISNUMBER(SEARCH("Handle",J:J)),"No's",IF(ISNUMBER(SEARCH("Gear",J:J)),"No's",IF(ISNUMBER(SEARCH("Bush",J:J)),"No's","")))))))))))))))))))) -> Sqmt | L26: 144 | T26: =IF(N26="","",SUM(N26,O26,P26,Q26,R26))
A27: =IF(C27="","",COUNT($C$3:C27)) -> 25 | B27: =IF(C27="","",TEXT(C27,"mmmm")) -> December | C27: 44926 | F27: Opening stock | G27: K Flex | J27: Insu Kflex Thermal 13mm | K27: =IF(ISNUMBER(SEARCH("gsm",J:J)),"Kg's",IF(ISNUMBER(SEARCH("Tape",J:J)),"Roll",IF(ISNUMBER(SEARCH("Thermal",J:J)),"Sqmt",IF(ISNUMBER(SEARCH("Acou",J:J)),"Sqmt",IF(ISNUMBER(SEARCH("ss",J:J)),"Kg's",IF(ISNUMBER(SEARCH("Alu",J:J)),"Kg's",IF(ISNUMBER(SEARCH("Gasket",J:J)),"Rmt",IF(ISNUMBER(SEARCH("Cleats",J:J)),"No's",IF(ISNUMBER(SEARCH("Tube",J:J)),"No's",IF(ISNUMBER(SEARCH("Bracket",J:J)),"No's",IF(ISNUMBER(SEARCH("Corner",J:J)),"No's",IF(ISNUMBER(SEARCH("MS",J:J)),"Kg's",IF(ISNUMBER(SEARCH("Bucket",J:J)),"Kg's",IF(ISNUMBER(SEARCH("stretch",J:J)),"Kg's",IF(ISNUMBER(SEARCH("Bubble",J:J)),"Roll",IF(ISNUMBER(SEARCH("JTR",J:J)),"Rmt",IF(ISNUMBER(SEARCH("Rod",J:J)),"Kg's",IF(ISNUMBER(SEARCH("Handle",J:J)),"No's",IF(ISNUMBER(SEARCH("Gear",J:J)),"No's",IF(ISNUMBER(SEARCH("Bush",J:J)),"No's","")))))))))))))))))))) -> Sqmt | L27: 33.6 | T27: =IF(N27="","",SUM(N27,O27,P27,Q27,R27))
A28: =IF(C28="","",COUNT($C$3:C28)) -> 26 | B28: =IF(C28="","",TEXT(C28,"mmmm")) -> December | C28: 44926 | F28: Opening stock | G28: K Flex | J28: Insu Kflex Thermal 25mm | K28: =IF(ISNUMBER(SEARCH("gsm",J:J)),"Kg's",IF(ISNUMBER(SEARCH("Tape",J:J)),"Roll",IF(ISNUMBER(SEARCH("Thermal",J:J)),"Sqmt",IF(ISNUMBER(SEARCH("Acou",J:J)),"Sqmt",IF(ISNUMBER(SEARCH("ss",J:J)),"Kg's",IF(ISNUMBER(SEARCH("Alu",J:J)),"Kg's",IF(ISNUMBER(SEARCH("Gasket",J:J)),"Rmt",IF(ISNUMBER(SEARCH("Cleats",J:J)),"No's",IF(ISNUMBER(SEARCH("Tube",J:J)),"No's",IF(ISNUMBER(SEARCH("Bracket",J:J)),"No's",IF(ISNUMBER(SEARCH("Corner",J:J)),"No's",IF(ISNUMBER(SEARCH("MS",J:J)),"Kg's",IF(ISNUMBER(SEARCH("Bucket",J:J)),"Kg's",IF(ISNUMBER(SEARCH("stretch",J:J)),"Kg's",IF(ISNUMBER(SEARCH("Bubble",J:J)),"Roll",IF(ISNUMBER(SEARCH("JTR",J:J)),"Rmt",IF(ISNUMBER(SEARCH("Rod",J:J)),"Kg's",IF(ISNUMBER(SEARCH("Handle",J:J)),"No's",IF(ISNUMBER(SEARCH("Gear",J:J)),"No's",IF(ISNUMBER(SEARCH("Bush",J:J)),"No's","")))))))))))))))))))) -> Sqmt | L28: 38.4
A29: =IF(C29="","",COUNT($C$3:C29)) -> 27 | B29: =IF(C29="","",TEXT(C29,"mmmm")) -> December | C29: 44926 | F29: Opening stock | G29: K Flex | J29: Insu Kflex Thermal 32mm | K29: =IF(ISNUMBER(SEARCH("gsm",J:J)),"Kg's",IF(ISNUMBER(SEARCH("Tape",J:J)),"Roll",IF(ISNUMBER(SEARCH("Thermal",J:J)),"Sqmt",IF(ISNUMBER(SEARCH("Acou",J:J)),"Sqmt",IF(ISNUMBER(SEARCH("ss",J:J)),"Kg's",IF(ISNUMBER(SEARCH("Alu",J:J)),"Kg's",IF(ISNUMBER(SEARCH("Gasket",J:J)),"Rmt",IF(ISNUMBER(SEARCH("Cleats",J:J)),"No's",IF(ISNUMBER(SEARCH("Tube",J:J)),"No's",IF(ISNUMBER(SEARCH("Bracket",J:J)),"No's",IF(ISNUMBER(SEARCH("Corner",J:J)),"No's",IF(ISNUMBER(SEARCH("MS",J:J)),"Kg's",IF(ISNUMBER(SEARCH("Bucket",J:J)),"Kg's",IF(ISNUMBER(SEARCH("stretch",J:J)),"Kg's",IF(ISNUMBER(SEARCH("Bubble",J:J)),"Roll",IF(ISNUMBER(SEARCH("JTR",J:J)),"Rmt",IF(ISNUMBER(SEARCH("Rod",J:J)),"Kg's",IF(ISNUMBER(SEARCH("Handle",J:J)),"No's",IF(ISNUMBER(SEARCH("Gear",J:J)),"No's",IF(ISNUMBER(SEARCH("Bush",J:J)),"No's","")))))))))))))))))))) -> Sqmt | L29: 93.6 | T29: =IF(N29="","",SUM(N29,O29,P29,Q29,R29))
A30: =IF(C30="","",COUNT($C$3:C30)) -> 28 | B30: =IF(C30="","",TEXT(C30,"mmmm")) -> December | C30: 44926 | F30: Opening stock | G30: K Flex | J30: Insu Kflex Thermal 9mm Al. Foil | K30: =IF(ISNUMBER(SEARCH("gsm",J:J)),"Kg's",IF(ISNUMBER(SEARCH("Tape",J:J)),"Roll",IF(ISNUMBER(SEARCH("Thermal",J:J)),"Sqmt",IF(ISNUMBER(SEARCH("Acou",J:J)),"Sqmt",IF(ISNUMBER(SEARCH("ss",J:J)),"Kg's",IF(ISNUMBER(SEARCH("Alu",J:J)),"Kg's",IF(ISNUMBER(SEARCH("Gasket",J:J)),"Rmt",IF(ISNUMBER(SEARCH("Cleats",J:J)),"No's",IF(ISNUMBER(SEARCH("Tube",J:J)),"No's",IF(ISNUMBER(SEARCH("Bracket",J:J)),"No's",IF(ISNUMBER(SEARCH("Corner",J:J)),"No's",IF(ISNUMBER(SEARCH("MS",J:J)),"Kg's",IF(ISNUMBER(SEARCH("Bucket",J:J)),"Kg's",IF(ISNUMBER(SEARCH("stretch",J:J)),"Kg's",IF(ISNUMBER(SEARCH("Bubble",J:J)),"Roll",IF(ISNUMBER(SEARCH("JTR",J:J)),"Rmt",IF(ISNUMBER(SEARCH("Rod",J:J)),"Kg's",IF(ISNUMBER(SEARCH("Handle",J:J)),"No's",IF(ISNUMBER(SEARCH("Gear",J:J)),"No's",IF(ISNUMBER(SEARCH("Bush",J:J)),"No's","")))))))))))))))))))) -> Sqmt | L30: 24
A31: =IF(C31="","",COUNT($C$3:C31)) -> 29 | B31: =IF(C31="","",TEXT(C31,"mmmm")) -> December | C31: 44926 | F31: Opening stock | G31: K Flex | J31: Insu Kflex Thermal 13mm Al. Foil | K31: =IF(ISNUMBER(SEARCH("gsm",J:J)),"Kg's",IF(ISNUMBER(SEARCH("Tape",J:J)),"Roll",IF(ISNUMBER(SEARCH("Thermal",J:J)),"Sqmt",IF(ISNUMBER(SEARCH("Acou",J:J)),"Sqmt",IF(ISNUMBER(SEARCH("ss",J:J)),"Kg's",IF(ISNUMBER(SEARCH("Alu",J:J)),"Kg's",IF(ISNUMBER(SEARCH("Gasket",J:J)),"Rmt",IF(ISNUMBER(SEARCH("Cleats",J:J)),"No's",IF(ISNUMBER(SEARCH("Tube",J:J)),"No's",IF(ISNUMBER(SEARCH("Bracket",J:J)),"No's",IF(ISNUMBER(SEARCH("Corner",J:J)),"No's",IF(ISNUMBER(SEARCH("MS",J:J)),"Kg's",IF(ISNUMBER(SEARCH("Bucket",J:J)),"Kg's",IF(ISNUMBER(SEARCH("stretch",J:J)),"Kg's",IF(ISNUMBER(SEARCH("Bubble",J:J)),"Roll",IF(ISNUMBER(SEARCH("JTR",J:J)),"Rmt",IF(ISNUMBER(SEARCH("Rod",J:J)),"Kg's",IF(ISNUMBER(SEARCH("Handle",J:J)),"No's",IF(ISNUMBER(SEARCH("Gear",J:J)),"No's",IF(ISNUMBER(SEARCH("Bush",J:J)),"No's","")))))))))))))))))))) -> Sqmt | L31: 67.2 | T31: =IF(N31="","",SUM(N31,O31,P31,Q31,R31))
A32: =IF(C32="","",COUNT($C$3:C32)) -> 30 | B32: =IF(C32="","",TEXT(C32,"mmmm")) -> December | C32: 44926 | F32: Opening stock | G32: K Flex | J32: Insu Kflex Thermal 19mm Al. Foil | K32: =IF(ISNUMBER(SEARCH("gsm",J:J)),"Kg's",IF(ISNUMBER(SEARCH("Tape",J:J)),"Roll",IF(ISNUMBER(SEARCH("Thermal",J:J)),"Sqmt",IF(ISNUMBER(SEARCH("Acou",J:J)),"Sqmt",IF(ISNUMBER(SEARCH("ss",J:J)),"Kg's",IF(ISNUMBER(SEARCH("Alu",J:J)),"Kg's",IF(ISNUMBER(SEARCH("Gasket",J:J)),"Rmt",IF(ISNUMBER(SEARCH("Cleats",J:J)),"No's",IF(ISNUMBER(SEARCH("Tube",J:J)),"No's",IF(ISNUMBER(SEARCH("Bracket",J:J)),"No's",IF(ISNUMBER(SEARCH("Corner",J:J)),"No's",IF(ISNUMBER(SEARCH("MS",J:J)),"Kg's",IF(ISNUMBER(SEARCH("Bucket",J:J)),"Kg's",IF(ISNUMBER(SEARCH("stretch",J:J)),"Kg's",IF(ISNUMBER(SEARCH("Bubble",J:J)),"Roll",IF(ISNUMBER(SEARCH("JTR",J:J)),"Rmt",IF(ISNUMBER(SEARCH("Rod",J:J)),"Kg's",IF(ISNUMBER(SEARCH("Handle",J:J)),"No's",IF(ISNUMBER(SEARCH("Gear",J:J)),"No's",IF(ISNUMBER(SEARCH("Bush",J:J)),"No's","")))))))))))))))))))) -> Sqmt | L32: 24
A33: =IF(C33="","",COUNT($C$3:C33)) -> 31 | B33: =IF(C33="","",TEXT(C33,"mmmm")) -> December | C33: 44926 | F33: Opening stock | G33: K Flex | J33: Insu Kflex Thermal 9mm (IC-Clad Black) | K33: =IF(ISNUMBER(SEARCH("gsm",J:J)),"Kg's",IF(ISNUMBER(SEARCH("Tape",J:J)),"Roll",IF(ISNUMBER(SEARCH("Thermal",J:J)),"Sqmt",IF(ISNUMBER(SEARCH("Acou",J:J)),"Sqmt",IF(ISNUMBER(SEARCH("ss",J:J)),"Kg's",IF(ISNUMBER(SEARCH("Alu",J:J)),"Kg's",IF(ISNUMBER(SEARCH("Gasket",J:J)),"Rmt",IF(ISNUMBER(SEARCH("Cleats",J:J)),"No's",IF(ISNUMBER(SEARCH("Tube",J:J)),"No's",IF(ISNUMBER(SEARCH("Bracket",J:J)),"No's",IF(ISNUMBER(SEARCH("Corner",J:J)),"No's",IF(ISNUMBER(SEARCH("MS",J:J)),"Kg's",IF(ISNUMBER(SEARCH("Bucket",J:J)),"Kg's",IF(ISNUMBER(SEARCH("stretch",J:J)),"Kg's",IF(ISNUMBER(SEARCH("Bubble",J:J)),"Roll",IF(ISNUMBER(SEARCH("JTR",J:J)),"Rmt",IF(ISNUMBER(SEARCH("Rod",J:J)),"Kg's",IF(ISNUMBER(SEARCH("Handle",J:J)),"No's",IF(ISNUMBER(SEARCH("Gear",J:J)),"No's",IF(ISNUMBER(SEARCH("Bush",J:J)),"No's","")))))))))))))))))))) -> Sqmt | L33: 120 | T33: =IF(N33="","",SUM(N33,O33,P33,Q33,R33))
A34: =IF(C34="","",COUNT($C$3:C34)) -> 32 | B34: =IF(C34="","",TEXT(C34,"mmmm")) -> December | C34: 44926 | F34: Opening stock | G34: K Flex | J34: Insu Kflex Thermal 13mm (IC-Clad Black) | K34: =IF(ISNUMBER(SEARCH("gsm",J:J)),"Kg's",IF(ISNUMBER(SEARCH("Tape",J:J)),"Roll",IF(ISNUMBER(SEARCH("Thermal",J:J)),"Sqmt",IF(ISNUMBER(SEARCH("Acou",J:J)),"Sqmt",IF(ISNUMBER(SEARCH("ss",J:J)),"Kg's",IF(ISNUMBER(SEARCH("Alu",J:J)),"Kg's",IF(ISNUMBER(SEARCH("Gasket",J:J)),"Rmt",IF(ISNUMBER(SEARCH("Cleats",J:J)),"No's",IF(ISNUMBER(SEARCH("Tube",J:J)),"No's",IF(ISNUMBER(SEARCH("Bracket",J:J)),"No's",IF(ISNUMBER(SEARCH("Corner",J:J)),"No's",IF(ISNUMBER(SEARCH("MS",J:J)),"Kg's",IF(ISNUMBER(SEARCH("Bucket",J:J)),"Kg's",IF(ISNUMBER(SEARCH("stretch",J:J)),"Kg's",IF(ISNUMBER(SEARCH("Bubble",J:J)),"Roll",IF(ISNUMBER(SEARCH("JTR",J:J)),"Rmt",IF(ISNUMBER(SEARCH("Rod",J:J)),"Kg's",IF(ISNUMBER(SEARCH("Handle",J:J)),"No's",IF(ISNUMBER(SEARCH("Gear",J:J)),"No's",IF(ISNUMBER(SEARCH("Bush",J:J)),"No's","")))))))))))))))))))) -> Sqmt | L34: 16.8
A35: =IF(C35="","",COUNT($C$3:C35)) -> 33 | B35: =IF(C35="","",TEXT(C35,"mmmm")) -> December | C35: 44926 | F35: Opening stock | G35: K Flex | J35: Insu Kflex Thermal 9mm (Clad Grey) | K35: =IF(ISNUMBER(SEARCH("gsm",J:J)),"Kg's",IF(ISNUMBER(SEARCH("Tape",J:J)),"Roll",IF(ISNUMBER(SEARCH("Thermal",J:J)),"Sqmt",IF(ISNUMBER(SEARCH("Acou",J:J)),"Sqmt",IF(ISNUMBER(SEARCH("ss",J:J)),"Kg's",IF(ISNUMBER(SEARCH("Alu",J:J)),"Kg's",IF(ISNUMBER(SEARCH("Gasket",J:J)),"Rmt",IF(ISNUMBER(SEARCH("Cleats",J:J)),"No's",IF(ISNUMBER(SEARCH("Tube",J:J)),"No's",IF(ISNUMBER(SEARCH("Bracket",J:J)),"No's",IF(ISNUMBER(SEARCH("Corner",J:J)),"No's",IF(ISNUMBER(SEARCH("MS",J:J)),"Kg's",IF(ISNUMBER(SEARCH("Bucket",J:J)),"Kg's",IF(ISNUMBER(SEARCH("stretch",J:J)),"Kg's",IF(ISNUMBER(SEARCH("Bubble",J:J)),"Roll",IF(ISNUMBER(SEARCH("JTR",J:J)),"Rmt",IF(ISNUMBER(SEARCH("Rod",J:J)),"Kg's",IF(ISNUMBER(SEARCH("Handle",J:J)),"No's",IF(ISNUMBER(SEARCH("Gear",J:J)),"No's",IF(ISNUMBER(SEARCH("Bush",J:J)),"No's","")))))))))))))))))))) -> Sqmt | L35: 24 | T35: =IF(N35="","",SUM(N35,O35,P35,Q35,R35))
A36: =IF(C36="","",COUNT($C$3:C36)) -> 34 | B36: =IF(C36="","",TEXT(C36,"mmmm")) -> December | C36: 44926 | F36: Opening stock | G36: K Flex | J36: Insu Kflex 10mm Acou. | K36: =IF(ISNUMBER(SEARCH("gsm",J:J)),"Kg's",IF(ISNUMBER(SEARCH("Tape",J:J)),"Roll",IF(ISNUMBER(SEARCH("Thermal",J:J)),"Sqmt",IF(ISNUMBER(SEARCH("Acou",J:J)),"Sqmt",IF(ISNUMBER(SEARCH("ss",J:J)),"Kg's",IF(ISNUMBER(SEARCH("Alu",J:J)),"Kg's",IF(ISNUMBER(SEARCH("Gasket",J:J)),"Rmt",IF(ISNUMBER(SEARCH("Cleats",J:J)),"No's",IF(ISNUMBER(SEARCH("Tube",J:J)),"No's",IF(ISNUMBER(SEARCH("Bracket",J:J)),"No's",IF(ISNUMBER(SEARCH("Corner",J:J)),"No's",IF(ISNUMBER(SEARCH("MS",J:J)),"Kg's",IF(ISNUMBER(SEARCH("Bucket",J:J)),"Kg's",IF(ISNUMBER(SEARCH("stretch",J:J)),"Kg's",IF(ISNUMBER(SEARCH("Bubble",J:J)),"Roll",IF(ISNUMBER(SEARCH("JTR",J:J)),"Rmt",IF(ISNUMBER(SEARCH("Rod",J:J)),"Kg's",IF(ISNUMBER(SEARCH("Handle",J:J)),"No's",IF(ISNUMBER(SEARCH("Gear",J:J)),"No's",IF(ISNUMBER(SEARCH("Bush",J:J)),"No's","")))))))))))))))))))) -> Sqmt | L36: 160 | T36: =IF(N36="","",SUM(N36,O36,P36,Q36,R36))
A37: =IF(C37="","",COUNT($C$3:C37)) -> 35 | B37: =IF(C37="","",TEXT(C37,"mmmm")) -> December | C37: 44926 | F37: Opening stock | G37: K Flex | J37: Insu Kflex 15mm Acou. | K37: =IF(ISNUMBER(SEARCH("gsm",J:J)),"Kg's",IF(ISNUMBER(SEARCH("Tape",J:J)),"Roll",IF(ISNUMBER(SEARCH("Thermal",J:J)),"Sqmt",IF(ISNUMBER(SEARCH("Acou",J:J)),"Sqmt",IF(ISNUMBER(SEARCH("ss",J:J)),"Kg's",IF(ISNUMBER(SEARCH("Alu",J:J)),"Kg's",IF(ISNUMBER(SEARCH("Gasket",J:J)),"Rmt",IF(ISNUMBER(SEARCH("Cleats",J:J)),"No's",IF(ISNUMBER(SEARCH("Tube",J:J)),"No's",IF(ISNUMBER(SEARCH("Bracket",J:J)),"No's",IF(ISNUMBER(SEARCH("Corner",J:J)),"No's",IF(ISNUMBER(SEARCH("MS",J:J)),"Kg's",IF(ISNUMBER(SEARCH("Bucket",J:J)),"Kg's",IF(ISNUMBER(SEARCH("stretch",J:J)),"Kg's",IF(ISNUMBER(SEARCH("Bubble",J:J)),"Roll",IF(ISNUMBER(SEARCH("JTR",J:J)),"Rmt",IF(ISNUMBER(SEARCH("Rod",J:J)),"Kg's",IF(ISNUMBER(SEARCH("Handle",J:J)),"No's",IF(ISNUMBER(SEARCH("Gear",J:J)),"No's",IF(ISNUMBER(SEARCH("Bush",J:J)),"No's","")))))))))))))))))))) -> Sqmt | L37: 185 | T37: =IF(N37="","",SUM(N37,O37,P37,Q37,R37))
A38: =IF(C38="","",COUNT($C$3:C38)) -> 36 | B38: =IF(C38="","",TEXT(C38,"mmmm")) -> December | C38: 44926 | F38: Opening stock | G38: K Flex | J38: Insu Thermal Tape | K38: =IF(ISNUMBER(SEARCH("gsm",J:J)),"Kg's",IF(ISNUMBER(SEARCH("Tape",J:J)),"Roll",IF(ISNUMBER(SEARCH("Thermal",J:J)),"Sqmt",IF(ISNUMBER(SEARCH("Acou",J:J)),"Sqmt",IF(ISNUMBER(SEARCH("ss",J:J)),"Kg's",IF(ISNUMBER(SEARCH("Alu",J:J)),"Kg's",IF(ISNUMBER(SEARCH("Gasket",J:J)),"Rmt",IF(ISNUMBER(SEARCH("Cleats",J:J)),"No's",IF(ISNUMBER(SEARCH("Tube",J:J)),"No's",IF(ISNUMBER(SEARCH("Bracket",J:J)),"No's",IF(ISNUMBER(SEARCH("Corner",J:J)),"No's",IF(ISNUMBER(SEARCH("MS",J:J)),"Kg's",IF(ISNUMBER(SEARCH("Bucket",J:J)),"Kg's",IF(ISNUMBER(SEARCH("stretch",J:J)),"Kg's",IF(ISNUMBER(SEARCH("Bubble",J:J)),"Roll",IF(ISNUMBER(SEARCH("JTR",J:J)),"Rmt",IF(ISNUMBER(SEARCH("Rod",J:J)),"Kg's",IF(ISNUMBER(SEARCH("Handle",J:J)),"No's",IF(ISNUMBER(SEARCH("Gear",J:J)),"No's",IF(ISNUMBER(SEARCH("Bush",J:J)),"No's","")))))))))))))))))))) -> Roll | L38: 277 | T38: =IF(N38="","",SUM(N38,O38,P38,Q38,R38))
A39: =IF(C39="","",COUNT($C$3:C39)) -> 37 | B39: =IF(C39="","",TEXT(C39,"mmmm")) -> December | C39: 44926 | F39: Opening stock | G39: K Flex | J39: Insu Thermal IC Clad Tape | K39: =IF(ISNUMBER(SEARCH("gsm",J:J)),"Kg's",IF(ISNUMBER(SEARCH("Tape",J:J)),"Roll",IF(ISNUMBER(SEARCH("Thermal",J:J)),"Sqmt",IF(ISNUMBER(SEARCH("Acou",J:J)),"Sqmt",IF(ISNUMBER(SEARCH("ss",J:J)),"Kg's",IF(ISNUMBER(SEARCH("Alu",J:J)),"Kg's",IF(ISNUMBER(SEARCH("Gasket",J:J)),"Rmt",IF(ISNUMBER(SEARCH("Cleats",J:J)),"No's",IF(ISNUMBER(SEARCH("Tube",J:J)),"No's",IF(ISNUMBER(SEARCH("Bracket",J:J)),"No's",IF(ISNUMBER(SEARCH("Corner",J:J)),"No's",IF(ISNUMBER(SEARCH("MS",J:J)),"Kg's",IF(ISNUMBER(SEARCH("Bucket",J:J)),"Kg's",IF(ISNUMBER(SEARCH("stretch",J:J)),"Kg's",IF(ISNUMBER(SEARCH("Bubble",J:J)),"Roll",IF(ISNUMBER(SEARCH("JTR",J:J)),"Rmt",IF(ISNUMBER(SEARCH("Rod",J:J)),"Kg's",IF(ISNUMBER(SEARCH("Handle",J:J)),"No's",IF(ISNUMBER(SEARCH("Gear",J:J)),"No's",IF(ISNUMBER(SEARCH("Bush",J:J)),"No's","")))))))))))))))))))) -> Roll | L39: 102 | T39: =IF(N39="","",SUM(N39,O39,P39,Q39,R39))
A40: =IF(C40="","",COUNT($C$3:C40)) -> 38 | B40: =IF(C40="","",TEXT(C40,"mmmm")) -> December | C40: 44926 | F40: Opening stock | G40: Superlon | J40: Insu Superlon Thermal 25mm | K40: =IF(ISNUMBER(SEARCH("gsm",J:J)),"Kg's",IF(ISNUMBER(SEARCH("Tape",J:J)),"Roll",IF(ISNUMBER(SEARCH("Thermal",J:J)),"Sqmt",IF(ISNUMBER(SEARCH("Acou",J:J)),"Sqmt",IF(ISNUMBER(SEARCH("ss",J:J)),"Kg's",IF(ISNUMBER(SEARCH("Alu",J:J)),"Kg's",IF(ISNUMBER(SEARCH("Gasket",J:J)),"Rmt",IF(ISNUMBER(SEARCH("Cleats",J:J)),"No's",IF(ISNUMBER(SEARCH("Tube",J:J)),"No's",IF(ISNUMBER(SEARCH("Bracket",J:J)),"No's",IF(ISNUMBER(SEARCH("Corner",J:J)),"No's",IF(ISNUMBER(SEARCH("MS",J:J)),"Kg's",IF(ISNUMBER(SEARCH("Bucket",J:J)),"Kg's",IF(ISNUMBER(SEARCH("stretch",J:J)),"Kg's",IF(ISNUMBER(SEARCH("Bubble",J:J)),"Roll",IF(ISNUMBER(SEARCH("JTR",J:J)),"Rmt",IF(ISNUMBER(SEARCH("Rod",J:J)),"Kg's",IF(ISNUMBER(SEARCH("Handle",J:J)),"No's",IF(ISNUMBER(SEARCH("Gear",J:J)),"No's",IF(ISNUMBER(SEARCH("Bush",J:J)),"No's","")))))))))))))))))))) -> Sqmt | L40: 11.15 | T40: =IF(N40="","",SUM(N40,O40,P40,Q40,R40))
...

Sheet Consumption
N1: SUM | O1: =SUM(O3:O1048576) -> 449468.27 | P1: =SUM(P3:P1048576) -> 70163.15 | Q1: =SUM(Q3:Q1048576) -> 64018.7 | R1: =AVERAGE(R3:R2087) -> 22.157623 | S1: =AVERAGE(S3:S2321) -> 77.625641 | T1: =SUM(T3:T1048576) -> 6251.2702 | U1: =SUM(U3:U1048576) -> 6110.55 | W1: =SUM(W3:W1048576) -> 32508.948 | X1: =SUM(X3:X1048576) -> 34376.953 | Y1: =AVERAGE(Y3:Y1048576) -> 14.886479 | Z1: =AVERAGE(Z3:Z1048576) -> 16.637762 | AA1: =SUM(AA3:AA1048576) -> 0 | AB1: =SUM(AB3:AB1048576) -> 34376.953
A2: SI NO | B2: MONTH | C2: DATE | D2: CUST. PO NO. | E2: KNND JOB NO | F2: PO DATE | G2: CUSTOMER NAME | H2: PROJECT NAME | I2: PRODUCT | J2: RAW MATERIAL | K2: UNITS | L2: PLANNING(Sqmt) | M2: S.LINE (Rmt) | N2: VULCAN (Rmt) | O2: FEED QTY | P2: BILL Qty Sqmt | Q2: Area+Fold | R2: Fitting (Straight) | S2: Ratio (Fitting) | T2: SCRAP Sqmt | U2: FOLD Sqmt | V2: CONSUMPTION | W2: FOLD Kg | X2: SCRAP Kg | Y2: SCRAP % | Z2: FOLD % | AA2: USED SCR Kg | AB2: Act SCRAP Kg | AC2: Remarks | AD2: Coil Number
A3: =IF(C3="","",COUNTA($C$3:C3)) -> 1 | B3: =IF(C3="","",TEXT(C3,"mmmm")) -> April | C3: 44655 | D3: 2302-64005 | F3: 44616 | G3: Knnd Associates Pvt Ltd | H3: Google Kyoto West Second Floor Oval Duct | I3: Spiral Oval Duct with Paint | J3: 120gsm Slit 24G | K3: =IF(ISNUMBER(SEARCH("gsm",J:J)),"Sqmt",IF(ISNUMBER(SEARCH("Tape",J:J)),"Roll",IF(ISNUMBER(SEARCH("Thermal",J:J)),"Sqmt",IF(ISNUMBER(SEARCH("Acou",J:J)),"Sqmt",IF(ISNUMBER(SEARCH("ss",J:J)),"Sqmt",IF(ISNUMBER(SEARCH("Alu",J:J)),"Sqmt",IF(ISNUMBER(SEARCH("Gasket",J:J)),"Rmt",IF(ISNUMBER(SEARCH("Cleats",J:J)),"No's",IF(ISNUMBER(SEARCH("Tube",J:J)),"No's",IF(ISNUMBER(SEARCH("Bracket",J:J)),"No's",IF(ISNUMBER(SEARCH("Corner",J:J)),"No's",IF(ISNUMBER(SEARCH("MS",J:J)),"Kg's",IF(ISNUMBER(SEARCH("Bucket",J:J)),"Kg's",IF(ISNUMBER(SEARCH("stretch",J:J)),"Kg's",IF(ISNUMBER(SEARCH("Bubble",J:J)),"Roll",IF(ISNUMBER(SEARCH("JTR",J:J)),"Rmt",IF(ISNUMBER(SEARCH("Clamp",J:J)),"No's",IF(ISNUMBER(SEARCH("PIR",J:J)),"sqmt","")))))))))))))))))) -> Sqmt | L3: 21.8 | M3: 17.868852 | O3: =IF(ISNUMBER(SEARCH("gsm",J:J)),(M3+N3)*1.22,IF(ISNUMBER(SEARCH("Tape",J:J)),L3,IF(ISNUMBER(SEARCH("Thermal",J:J)),L3,IF(ISNUMBER(SEARCH("Acou",J:J)),L3,IF(ISNUMBER(SEARCH("ss",J:J)),L3,IF(ISNUMBER(SEARCH("Alu",J:J)),L3,IF(ISNUMBER(SEARCH("Gasket",J:J)),L3,IF(ISNUMBER(SEARCH("Cleats",J:J)),L3,IF(ISNUMBER(SEARCH("Tube",J:J)),L3,IF(ISNUMBER(SEARCH("Bracket",J:J)),L3,IF(ISNUMBER(SEARCH("Corner",J:J)),L3,IF(ISNUMBER(SEARCH("MS",J:J)),L3,IF(ISNUMBER(SEARCH("Bucket",J:J)),L3,IF(ISNUMBER(SEARCH("stretch",J:J)),L3,IF(ISNUMBER(SEARCH("Bubble",J:J)),L3,IF(ISNUMBER(SEARCH("JTR",J:J)),L3,IF(ISNUMBER(SEARCH("Clamp",J:J)),"No's",IF(ISNUMBER(SEARCH("PIR",J:J)),"sqmt","")))))))))))))))))) -> 21.8 | P3: 13.1 | Q3: 13.5 | R3: 37 | S3: 63 | T3: =(IF(K3="Sqmt",(O3-Q3),"")) -> 8.3 | U3: =(IF(K3="Sqmt",(O3-P3)-T3,IF(K3="Rmt","",IF(K3="Kg's","",IF(K3="No's","",IF(K3="Roll","","")))))) -> 0.4 | V3: =IF(ISNUMBER(SEARCH("26",J:J)),O3*3.925,IF(ISNUMBER(SEARCH("24",J:J)),O3*4.71,IF(ISNUMBER(SEARCH("22",J:J)),O3*6.28,IF(ISNUMBER(SEARCH("20",J:J)),O3*7.85,IF(ISNUMBER(SEARCH("18G",J:J)),O3*9.42,IF(ISNUMBER(SEARCH("16G",J:J)),O3*11.775,IF(ISNUMBER(SEARCH("Thermal",J:J)),O3,IF(ISNUMBER(SEARCH("Acou",J:J)),O3,IF(ISNUMBER(SEARCH("ss",J:J)),O3,IF(ISNUMBER(SEARCH("0.8mm",J:J)),O3*2.2,IF(ISNUMBER(SEARCH("1mm",J:J)),O3*2.75,IF(ISNUMBER(SEARCH("1.2mm",J:J)),O3*3.3,IF(ISNUMBER(SEARCH("Gasket",J:J)),O3,IF(ISNUMBER(SEARCH("Cleats",J:J)),O3,IF(ISNUMBER(SEARCH("Sealant",J:J)),O3,IF(ISNUMBER(SEARCH("Bracket",J:J)),O3,IF(ISNUMBER(SEARCH("Corner",J:J)),O3,IF(ISNUMBER(SEARCH("Bubble",J:J)),O3,"")))))))))))))))))) -> 102.678 | W3: =IF(ISNUMBER(SEARCH("26",J:J)),U3*3.925,IF(ISNUMBER(SEARCH("24",J:J)),U3*4.71,IF(ISNUMBER(SEARCH("22",J:J)),U3*6.28,IF(ISNUMBER(SEARCH("20",J:J)),U3*7.85,IF(ISNUMBER(SEARCH("18G",J:J)),U3*9.42,IF(ISNUMBER(SEARCH("16G",J:J)),U3*11.775,IF(ISNUMBER(SEARCH("Thermal",J:J)),U3,IF(ISNUMBER(SEARCH("Acou",J:J)),U3,IF(ISNUMBER(SEARCH("ss",J:J)),U3,IF(ISNUMBER(SEARCH("0.8mm",J:J)),U3*2.2,IF(ISNUMBER(SEARCH("1mm",J:J)),U3*2.75,IF(ISNUMBER(SEARCH("1.2mm",J:J)),U3*3.3,IF(ISNUMBER(SEARCH("Gasket",J:J)),U3,IF(ISNUMBER(SEARCH("Cleats",J:J)),U3,IF(ISNUMBER(SEARCH("Sealant",J:J)),U3,IF(ISNUMBER(SEARCH("Bracket",J:J)),U3,IF(ISNUMBER(SEARCH("Corner",J:J)),U3,IF(ISNUMBER(SEARCH("Bubble",J:J)),U3,"")))))))))))))))))) -> 1.884 | X3: =IF(ISNUMBER(SEARCH("26",J:J)),T3*3.925,IF(ISNUMBER(SEARCH("24",J:J)),T3*4.71,IF(ISNUMBER(SEARCH("22",J:J)),T3*6.28,IF(ISNUMBER(SEARCH("20",J:J)),T3*7.85,IF(ISNUMBER(SEARCH("18",J:J)),T3*9.42,IF(ISNUMBER(SEARCH("16",J:J)),T3*11.775,IF(ISNUMBER(SEARCH("Thermal",J:J)),"",IF(ISNUMBER(SEARCH("Acou",J:J)),"",IF(ISNUMBER(SEARCH("ss",J:J)),"",IF(ISNUMBER(SEARCH("0.8mm",J:J)),T3*2.2,IF(ISNUMBER(SEARCH("1mm",J:J)),T3*2.75,IF(ISNUMBER(SEARCH("1.2mm",J:J)),T3*3.3,IF(ISNUMBER(SEARCH("Gasket",J:J)),"",IF(ISNUMBER(SEARCH("Cleats",J:J)),"",IF(ISNUMBER(SEARCH("Sealant",J:J)),"",IF(ISNUMBER(SEARCH("Bracket",J:J)),"",IF(ISNUMBER(SEARCH("Corner",J:J)),"",IF(ISNUMBER(SEARCH("Bubble",J:J)),"","")))))))))))))))))) -> 39.093 | Y3: =IF(K3="Sqmt",(T3/O3)*100,IF(K3="Kg's","",IF(K3="No's","",IF(K3="Rmt","",IF(K3="Roll","",IF(K3="","")))))) -> 38.073394 | Z3: =IF(K3="Sqmt",(U3/O3)*100,IF(K3="Kg's","",IF(K3="No's","",IF(K3="Rmt","",IF(K3="Roll","",IF(K3="","")))))) -> 1.8348624 | AB3: =IFERROR((X3-AA3),"") -> 39.093
A4: =IF(C4="","",COUNTA($C$3:C4)) -> 2 | B4: =IF(C4="","",TEXT(C4,"mmmm")) -> April | C4: 44655 | D4: 2302-64005 | F4: 44616 | G4: Knnd Associates Pvt Ltd | H4: Google Kyoto West Second Floor Oval Duct | I4: Spiral Oval Duct with Paint | J4: 120gsm 24G | K4: =IF(ISNUMBER(SEARCH("gsm",J:J)),"Sqmt",IF(ISNUMBER(SEARCH("Tape",J:J)),"Roll",IF(ISNUMBER(SEARCH("Thermal",J:J)),"Sqmt",IF(ISNUMBER(SEARCH("Acou",J:J)),"Sqmt",IF(ISNUMBER(SEARCH("ss",J:J)),"Sqmt",IF(ISNUMBER(SEARCH("Alu",J:J)),"Sqmt",IF(ISNUMBER(SEARCH("Gasket",J:J)),"Rmt",IF(ISNUMBER(SEARCH("Cleats",J:J)),"No's",IF(ISNUMBER(SEARCH("Tube",J:J)),"No's",IF(ISNUMBER(SEARCH("Bracket",J:J)),"No's",IF(ISNUMBER(SEARCH("Corner",J:J)),"No's",IF(ISNUMBER(SEARCH("MS",J:J)),"Kg's",IF(ISNUMBER(SEARCH("Bucket",J:J)),"Kg's",IF(ISNUMBER(SEARCH("stretch",J:J)),"Kg's",IF(ISNUMBER(SEARCH("Bubble",J:J)),"Roll",IF(ISNUMBER(SEARCH("JTR",J:J)),"Rmt",IF(ISNUMBER(SEARCH("Clamp",J:J)),"No's",IF(ISNUMBER(SEARCH("PIR",J:J)),"sqmt","")))))))))))))))))) -> Sqmt | L4: 48.7 | N4: 39.918033 | O4: =IF(ISNUMBER(SEARCH("gsm",J:J)),(M4+N4)*1.22,IF(ISNUMBER(SEARCH("Tape",J:J)),L4,IF(ISNUMBER(SEARCH("Thermal",J:J)),L4,IF(ISNUMBER(SEARCH("Acou",J:J)),L4,IF(ISNUMBER(SEARCH("ss",J:J)),L4,IF(ISNUMBER(SEARCH("Alu",J:J)),L4,IF(ISNUMBER(SEARCH("Gasket",J:J)),L4,IF(ISNUMBER(SEARCH("Cleats",J:J)),L4,IF(ISNUMBER(SEARCH("Tube",J:J)),L4,IF(ISNUMBER(SEARCH("Bracket",J:J)),L4,IF(ISNUMBER(SEARCH("Corner",J:J)),L4,IF(ISNUMBER(SEARCH("MS",J:J)),L4,IF(ISNUMBER(SEARCH("Bucket",J:J)),L4,IF(ISNUMBER(SEARCH("stretch",J:J)),L4,IF(ISNUMBER(SEARCH("Bubble",J:J)),L4,IF(ISNUMBER(SEARCH("JTR",J:J)),L4,IF(ISNUMBER(SEARCH("Clamp",J:J)),"No's",IF(ISNUMBER(SEARCH("PIR",J:J)),"sqmt","")))))))))))))))))) -> 48.7 | P4: 37.1 | Q4: 43.8 | T4: =(IF(K4="Sqmt",(O4-Q4),"")) -> 4.9 | U4: =(IF(K4="Sqmt",(O4-P4)-T4,IF(K4="Rmt","",IF(K4="Kg's","",IF(K4="No's","",IF(K4="Roll","","")))))) -> 6.7 | V4: =IF(ISNUMBER(SEARCH("26",J:J)),O4*3.925,IF(ISNUMBER(SEARCH("24",J:J)),O4*4.71,IF(ISNUMBER(SEARCH("22",J:J)),O4*6.28,IF(ISNUMBER(SEARCH("20",J:J)),O4*7.85,IF(ISNUMBER(SEARCH("18G",J:J)),O4*9.42,IF(ISNUMBER(SEARCH("16G",J:J)),O4*11.775,IF(ISNUMBER(SEARCH("Thermal",J:J)),O4,IF(ISNUMBER(SEARCH("Acou",J:J)),O4,IF(ISNUMBER(SEARCH("ss",J:J)),O4,IF(ISNUMBER(SEARCH("0.8mm",J:J)),O4*2.2,IF(ISNUMBER(SEARCH("1mm",J:J)),O4*2.75,IF(ISNUMBER(SEARCH("1.2mm",J:J)),O4*3.3,IF(ISNUMBER(SEARCH("Gasket",J:J)),O4,IF(ISNUMBER(SEARCH("Cleats",J:J)),O4,IF(ISNUMBER(SEARCH("Sealant",J:J)),O4,IF(ISNUMBER(SEARCH("Bracket",J:J)),O4,IF(ISNUMBER(SEARCH("Corner",J:J)),O4,IF(ISNUMBER(SEARCH("Bubble",J:J)),O4,"")))))))))))))))))) -> 229.377 | W4: =IF(ISNUMBER(SEARCH("26",J:J)),U4*3.925,IF(ISNUMBER(SEARCH("24",J:J)),U4*4.71,IF(ISNUMBER(SEARCH("22",J:J)),U4*6.28,IF(ISNUMBER(SEARCH("20",J:J)),U4*7.85,IF(ISNUMBER(SEARCH("18G",J:J)),U4*9.42,IF(ISNUMBER(SEARCH("16G",J:J)),U4*11.775,IF(ISNUMBER(SEARCH("Thermal",J:J)),U4,IF(ISNUMBER(SEARCH("Acou",J:J)),U4,IF(ISNUMBER(SEARCH("ss",J:J)),U4,IF(ISNUMBER(SEARCH("0.8mm",J:J)),U4*2.2,IF(ISNUMBER(SEARCH("1mm",J:J)),U4*2.75,IF(ISNUMBER(SEARCH("1.2mm",J:J)),U4*3.3,IF(ISNUMBER(SEARCH("Gasket",J:J)),U4,IF(ISNUMBER(SEARCH("Cleats",J:J)),U4,IF(ISNUMBER(SEARCH("Sealant",J:J)),U4,IF(ISNUMBER(SEARCH("Bracket",J:J)),U4,IF(ISNUMBER(SEARCH("Corner",J:J)),U4,IF(ISNUMBER(SEARCH("Bubble",J:J)),U4,"")))))))))))))))))) -> 31.557 | X4: =IF(ISNUMBER(SEARCH("26",J:J)),T4*3.925,IF(ISNUMBER(SEARCH("24",J:J)),T4*4.71,IF(ISNUMBER(SEARCH("22",J:J)),T4*6.28,IF(ISNUMBER(SEARCH("20",J:J)),T4*7.85,IF(ISNUMBER(SEARCH("18",J:J)),T4*9.42,IF(ISNUMBER(SEARCH("16",J:J)),T4*11.775,IF(ISNUMBER(SEARCH("Thermal",J:J)),"",IF(ISNUMBER(SEARCH("Acou",J:J)),"",IF(ISNUMBER(SEARCH("ss",J:J)),"",IF(ISNUMBER(SEARCH("0.8mm",J:J)),T4*2.2,IF(ISNUMBER(SEARCH("1mm",J:J)),T4*2.75,IF(ISNUMBER(SEARCH("1.2mm",J:J)),T4*3.3,IF(ISNUMBER(SEARCH("Gasket",J:J)),"",IF(ISNUMBER(SEARCH("Cleats",J:J)),"",IF(ISNUMBER(SEARCH("Sealant",J:J)),"",IF(ISNUMBER(SEARCH("Bracket",J:J)),"",IF(ISNUMBER(SEARCH("Corner",J:J)),"",IF(ISNUMBER(SEARCH("Bubble",J:J)),"","")))))))))))))))))) -> 23.079 | Y4: =IF(K4="Sqmt",(T4/O4)*100,IF(K4="Kg's","",IF(K4="No's","",IF(K4="Rmt","",IF(K4="Roll","",IF(K4="","")))))) -> 10.061602 | Z4: =IF(K4="Sqmt",(U4/O4)*100,IF(K4="Kg's","",IF(K4="No's","",IF(K4="Rmt","",IF(K4="Roll","",IF(K4="","")))))) -> 13.7577 | AB4: =IFERROR((X4-AA4),"") -> 23.079
A5: =IF(C5="","",COUNTA($C$3:C5)) -> 3 | B5: =IF(C5="","",TEXT(C5,"mmmm")) -> April | C5: 44655 | D5: 2302-64005 | F5: 44616 | G5: Knnd Associates Pvt Ltd | H5: Google Kyoto West Second Floor Oval Duct | I5: Spiral Oval Duct with Paint | J5: 120gsm Slit 22G | K5: =IF(ISNUMBER(SEARCH("gsm",J:J)),"Sqmt",IF(ISNUMBER(SEARCH("Tape",J:J)),"Roll",IF(ISNUMBER(SEARCH("Thermal",J:J)),"Sqmt",IF(ISNUMBER(SEARCH("Acou",J:J)),"Sqmt",IF(ISNUMBER(SEARCH("ss",J:J)),"Sqmt",IF(ISNUMBER(SEARCH("Alu",J:J)),"Sqmt",IF(ISNUMBER(SEARCH("Gasket",J:J)),"Rmt",IF(ISNUMBER(SEARCH("Cleats",J:J)),"No's",IF(ISNUMBER(SEARCH("Tube",J:J)),"No's",IF(ISNUMBER(SEARCH("Bracket",J:J)),"No's",IF(ISNUMBER(SEARCH("Corner",J:J)),"No's",IF(ISNUMBER(SEARCH("MS",J:J)),"Kg's",IF(ISNUMBER(SEARCH("Bucket",J:J)),"Kg's",IF(ISNUMBER(SEARCH("stretch",J:J)),"Kg's",IF(ISNUMBER(SEARCH("Bubble",J:J)),"Roll",IF(ISNUMBER(SEARCH("JTR",J:J)),"Rmt",IF(ISNUMBER(SEARCH("Clamp",J:J)),"No's",IF(ISNUMBER(SEARCH("PIR",J:J)),"sqmt","")))))))))))))))))) -> Sqmt | L5: 32.8 | M5: 26.885246 | O5: =IF(ISNUMBER(SEARCH("gsm",J:J)),(M5+N5)*1.22,IF(ISNUMBER(SEARCH("Tape",J:J)),L5,IF(ISNUMBER(SEARCH("Thermal",J:J)),L5,IF(ISNUMBER(SEARCH("Acou",J:J)),L5,IF(ISNUMBER(SEARCH("ss",J:J)),L5,IF(ISNUMBER(SEARCH("Alu",J:J)),L5,IF(ISNUMBER(SEARCH("Gasket",J:J)),L5,IF(ISNUMBER(SEARCH("Cleats",J:J)),L5,IF(ISNUMBER(SEARCH("Tube",J:J)),L5,IF(ISNUMBER(SEARCH("Bracket",J:J)),L5,IF(ISNUMBER(SEARCH("Corner",J:J)),L5,IF(ISNUMBER(SEARCH("MS",J:J)),L5,IF(ISNUMBER(SEARCH("Bucket",J:J)),L5,IF(ISNUMBER(SEARCH("stretch",J:J)),L5,IF(ISNUMBER(SEARCH("Bubble",J:J)),L5,IF(ISNUMBER(SEARCH("JTR",J:J)),L5,IF(ISNUMBER(SEARCH("Clamp",J:J)),"No's",IF(ISNUMBER(SEARCH("PIR",J:J)),"sqmt","")))))))))))))))))) -> 32.8 | P5: 25.5 | Q5: 26.1 | T5: =(IF(K5="Sqmt",(O5-Q5),"")) -> 6.7 | U5: =(IF(K5="Sqmt",(O5-P5)-T5,IF(K5="Rmt","",IF(K5="Kg's","",IF(K5="No's","",IF(K5="Roll","","")))))) -> 0.6 | V5: =IF(ISNUMBER(SEARCH("26",J:J)),O5*3.925,IF(ISNUMBER(SEARCH("24",J:J)),O5*4.71,IF(ISNUMBER(SEARCH("22",J:J)),O5*6.28,IF(ISNUMBER(SEARCH("20",J:J)),O5*7.85,IF(ISNUMBER(SEARCH("18G",J:J)),O5*9.42,IF(ISNUMBER(SEARCH("16G",J:J)),O5*11.775,IF(ISNUMBER(SEARCH("Thermal",J:J)),O5,IF(ISNUMBER(SEARCH("Acou",J:J)),O5,IF(ISNUMBER(SEARCH("ss",J:J)),O5,IF(ISNUMBER(SEARCH("0.8mm",J:J)),O5*2.2,IF(ISNUMBER(SEARCH("1mm",J:J)),O5*2.75,IF(ISNUMBER(SEARCH("1.2mm",J:J)),O5*3.3,IF(ISNUMBER(SEARCH("Gasket",J:J)),O5,IF(ISNUMBER(SEARCH("Cleats",J:J)),O5,IF(ISNUMBER(SEARCH("Sealant",J:J)),O5,IF(ISNUMBER(SEARCH("Bracket",J:J)),O5,IF(ISNUMBER(SEARCH("Corner",J:J)),O5,IF(ISNUMBER(SEARCH("Bubble",J:J)),O5,"")))))))))))))))))) -> 205.984 | W5: =IF(ISNUMBER(SEARCH("26",J:J)),U5*3.925,IF(ISNUMBER(SEARCH("24",J:J)),U5*4.71,IF(ISNUMBER(SEARCH("22",J:J)),U5*6.28,IF(ISNUMBER(SEARCH("20",J:J)),U5*7.85,IF(ISNUMBER(SEARCH("18G",J:J)),U5*9.42,IF(ISNUMBER(SEARCH("16G",J:J)),U5*11.775,IF(ISNUMBER(SEARCH("Thermal",J:J)),U5,IF(ISNUMBER(SEARCH("Acou",J:J)),U5,IF(ISNUMBER(SEARCH("ss",J:J)),U5,IF(ISNUMBER(SEARCH("0.8mm",J:J)),U5*2.2,IF(ISNUMBER(SEARCH("1mm",J:J)),U5*2.75,IF(ISNUMBER(SEARCH("1.2mm",J:J)),U5*3.3,IF(ISNUMBER(SEARCH("Gasket",J:J)),U5,IF(ISNUMBER(SEARCH("Cleats",J:J)),U5,IF(ISNUMBER(SEARCH("Sealant",J:J)),U5,IF(ISNUMBER(SEARCH("Bracket",J:J)),U5,IF(ISNUMBER(SEARCH("Corner",J:J)),U5,IF(ISNUMBER(SEARCH("Bubble",J:J)),U5,"")))))))))))))))))) -> 3.768 | X5: =IF(ISNUMBER(SEARCH("26",J:J)),T5*3.925,IF(ISNUMBER(SEARCH("24",J:J)),T5*4.71,IF(ISNUMBER(SEARCH("22",J:J)),T5*6.28,IF(ISNUMBER(SEARCH("20",J:J)),T5*7.85,IF(ISNUMBER(SEARCH("18",J:J)),T5*9.42,IF(ISNUMBER(SEARCH("16",J:J)),T5*11.775,IF(ISNUMBER(SEARCH("Thermal",J:J)),"",IF(ISNUMBER(SEARCH("Acou",J:J)),"",IF(ISNUMBER(SEARCH("ss",J:J)),"",IF(ISNUMBER(SEARCH("0.8mm",J:J)),T5*2.2,IF(ISNUMBER(SEARCH("1mm",J:J)),T5*2.75,IF(ISNUMBER(SEARCH("1.2mm",J:J)),T5*3.3,IF(ISNUMBER(SEARCH("Gasket",J:J)),"",IF(ISNUMBER(SEARCH("Cleats",J:J)),"",IF(ISNUMBER(SEARCH("Sealant",J:J)),"",IF(ISNUMBER(SEARCH("Bracket",J:J)),"",IF(ISNUMBER(SEARCH("Corner",J:J)),"",IF(ISNUMBER(SEARCH("Bubble",J:J)),"","")))))))))))))))))) -> 42.076 | Y5: =IF(K5="Sqmt",(T5/O5)*100,IF(K5="Kg's","",IF(K5="No's","",IF(K5="Rmt","",IF(K5="Roll","",IF(K5="","")))))) -> 20.426829 | Z5: =IF(K5="Sqmt",(U5/O5)*100,IF(K5="Kg's","",IF(K5="No's","",IF(K5="Rmt","",IF(K5="Roll","",IF(K5="","")))))) -> 1.8292683 | AB5: =IFERROR((X5-AA5),"") -> 42.076
A6: =IF(C6="","",COUNTA($C$3:C6)) -> 4 | B6: =IF(C6="","",TEXT(C6,"mmmm")) -> April | C6: 44655 | D6: 2302-64005 | F6: 44616 | G6: Knnd Associates Pvt Ltd | H6: Google Kyoto West Second Floor Oval Duct | I6: Spiral Oval Duct with Paint | J6: 120gsm 22G | K6: =IF(ISNUMBER(SEARCH("gsm",J:J)),"Sqmt",IF(ISNUMBER(SEARCH("Tape",J:J)),"Roll",IF(ISNUMBER(SEARCH("Thermal",J:J)),"Sqmt",IF(ISNUMBER(SEARCH("Acou",J:J)),"Sqmt",IF(ISNUMBER(SEARCH("ss",J:J)),"Sqmt",IF(ISNUMBER(SEARCH("Alu",J:J)),"Sqmt",IF(ISNUMBER(SEARCH("Gasket",J:J)),"Rmt",IF(ISNUMBER(SEARCH("Cleats",J:J)),"No's",IF(ISNUMBER(SEARCH("Tube",J:J)),"No's",IF(ISNUMBER(SEARCH("Bracket",J:J)),"No's",IF(ISNUMBER(SEARCH("Corner",J:J)),"No's",IF(ISNUMBER(SEARCH("MS",J:J)),"Kg's",IF(ISNUMBER(SEARCH("Bucket",J:J)),"Kg's",IF(ISNUMBER(SEARCH("stretch",J:J)),"Kg's",IF(ISNUMBER(SEARCH("Bubble",J:J)),"Roll",IF(ISNUMBER(SEARCH("JTR",J:J)),"Rmt",IF(ISNUMBER(SEARCH("Clamp",J:J)),"No's",IF(ISNUMBER(SEARCH("PIR",J:J)),"sqmt","")))))))))))))))))) -> Sqmt | L6: 45.7 | N6: 37.459016 | O6: =IF(ISNUMBER(SEARCH("gsm",J:J)),(M6+N6)*1.22,IF(ISNUMBER(SEARCH("Tape",J:J)),L6,IF(ISNUMBER(SEARCH("Thermal",J:J)),L6,IF(ISNUMBER(SEARCH("Acou",J:J)),L6,IF(ISNUMBER(SEARCH("ss",J:J)),L6,IF(ISNUMBER(SEARCH("Alu",J:J)),L6,IF(ISNUMBER(SEARCH("Gasket",J:J)),L6,IF(ISNUMBER(SEARCH("Cleats",J:J)),L6,IF(ISNUMBER(SEARCH("Tube",J:J)),L6,IF(ISNUMBER(SEARCH("Bracket",J:J)),L6,IF(ISNUMBER(SEARCH("Corner",J:J)),L6,IF(ISNUMBER(SEARCH("MS",J:J)),L6,IF(ISNUMBER(SEARCH("Bucket",J:J)),L6,IF(ISNUMBER(SEARCH("stretch",J:J)),L6,IF(ISNUMBER(SEARCH("Bubble",J:J)),L6,IF(ISNUMBER(SEARCH("JTR",J:J)),L6,IF(ISNUMBER(SEARCH("Clamp",J:J)),"No's",IF(ISNUMBER(SEARCH("PIR",J:J)),"sqmt","")))))))))))))))))) -> 45.7 | P6: 30.5 | Q6: 34.6 | T6: =(IF(K6="Sqmt",(O6-Q6),"")) -> 11.1 | U6: =(IF(K6="Sqmt",(O6-P6)-T6,IF(K6="Rmt","",IF(K6="Kg's","",IF(K6="No's","",IF(K6="Roll","","")))))) -> 4.1 | V6: =IF(ISNUMBER(SEARCH("26",J:J)),O6*3.925,IF(ISNUMBER(SEARCH("24",J:J)),O6*4.71,IF(ISNUMBER(SEARCH("22",J:J)),O6*6.28,IF(ISNUMBER(SEARCH("20",J:J)),O6*7.85,IF(ISNUMBER(SEARCH("18G",J:J)),O6*9.42,IF(ISNUMBER(SEARCH("16G",J:J)),O6*11.775,IF(ISNUMBER(SEARCH("Thermal",J:J)),O6,IF(ISNUMBER(SEARCH("Acou",J:J)),O6,IF(ISNUMBER(SEARCH("ss",J:J)),O6,IF(ISNUMBER(SEARCH("0.8mm",J:J)),O6*2.2,IF(ISNUMBER(SEARCH("1mm",J:J)),O6*2.75,IF(ISNUMBER(SEARCH("1.2mm",J:J)),O6*3.3,IF(ISNUMBER(SEARCH("Gasket",J:J)),O6,IF(ISNUMBER(SEARCH("Cleats",J:J)),O6,IF(ISNUMBER(SEARCH("Sealant",J:J)),O6,IF(ISNUMBER(SEARCH("Bracket",J:J)),O6,IF(ISNUMBER(SEARCH("Corner",J:J)),O6,IF(ISNUMBER(SEARCH("Bubble",J:J)),O6,"")))))))))))))))))) -> 286.996 | W6: =IF(ISNUMBER(SEARCH("26",J:J)),U6*3.925,IF(ISNUMBER(SEARCH("24",J:J)),U6*4.71,IF(ISNUMBER(SEARCH("22",J:J)),U6*6.28,IF(ISNUMBER(SEARCH("20",J:J)),U6*7.85,IF(ISNUMBER(SEARCH("18G",J:J)),U6*9.42,IF(ISNUMBER(SEARCH("16G",J:J)),U6*11.775,IF(ISNUMBER(SEARCH("Thermal",J:J)),U6,IF(ISNUMBER(SEARCH("Acou",J:J)),U6,IF(ISNUMBER(SEARCH("ss",J:J)),U6,IF(ISNUMBER(SEARCH("0.8mm",J:J)),U6*2.2,IF(ISNUMBER(SEARCH("1mm",J:J)),U6*2.75,IF(ISNUMBER(SEARCH("1.2mm",J:J)),U6*3.3,IF(ISNUMBER(SEARCH("Gasket",J:J)),U6,IF(ISNUMBER(SEARCH("Cleats",J:J)),U6,IF(ISNUMBER(SEARCH("Sealant",J:J)),U6,IF(ISNUMBER(SEARCH("Bracket",J:J)),U6,IF(ISNUMBER(SEARCH("Corner",J:J)),U6,IF(ISNUMBER(SEARCH("Bubble",J:J)),U6,"")))))))))))))))))) -> 25.748 | X6: =IF(ISNUMBER(SEARCH("26",J:J)),T6*3.925,IF(ISNUMBER(SEARCH("24",J:J)),T6*4.71,IF(ISNUMBER(SEARCH("22",J:J)),T6*6.28,IF(ISNUMBER(SEARCH("20",J:J)),T6*7.85,IF(ISNUMBER(SEARCH("18",J:J)),T6*9.42,IF(ISNUMBER(SEARCH("16",J:J)),T6*11.775,IF(ISNUMBER(SEARCH("Thermal",J:J)),"",IF(ISNUMBER(SEARCH("Acou",J:J)),"",IF(ISNUMBER(SEARCH("ss",J:J)),"",IF(ISNUMBER(SEARCH("0.8mm",J:J)),T6*2.2,IF(ISNUMBER(SEARCH("1mm",J:J)),T6*2.75,IF(ISNUMBER(SEARCH("1.2mm",J:J)),T6*3.3,IF(ISNUMBER(SEARCH("Gasket",J:J)),"",IF(ISNUMBER(SEARCH("Cleats",J:J)),"",IF(ISNUMBER(SEARCH("Sealant",J:J)),"",IF(ISNUMBER(SEARCH("Bracket",J:J)),"",IF(ISNUMBER(SEARCH("Corner",J:J)),"",IF(ISNUMBER(SEARCH("Bubble",J:J)),"","")))))))))))))))))) -> 69.708 | Y6: =IF(K6="Sqmt",(T6/O6)*100,IF(K6="Kg's","",IF(K6="No's","",IF(K6="Rmt","",IF(K6="Roll","",IF(K6="","")))))) -> 24.28884 | Z6: =IF(K6="Sqmt",(U6/O6)*100,IF(K6="Kg's","",IF(K6="No's","",IF(K6="Rmt","",IF(K6="Roll","",IF(K6="","")))))) -> 8.9715536 | AB6: =IFERROR((X6-AA6),"") -> 69.708
