Workbook
Name Raw_Material: OFFSET('[1]Raw material'!$D$2,,,COUNTIF('[1]Raw material'!$D:$D,"*?")-1)

Sheet Summary
B2: CAMDUCT INDIA PVT LTD
B3: Factory Physical Stock Summary as on 31.03.2026
B4: Sl No | C4: Description | D4: Taxable Value
B5: 1 | C5: Coils and Raw Materials | D5: ='Coil & Raw Materials'!C12 -> 18240248
B6: 2 | C6: Insulation Materials | D6: =Insulation!C12 -> 8683027.5
B7: 3 | C7: Finished Goods | D7: ='Finished Goods'!C6 -> 2719088
B8: 4 | C8: Consumable Items | D8: ='Consumables '!G118 -> 425550
B9: 5 | C9: Tools & Electrical Items | D9: ='Tools & Electrical'!C5 -> 145148
B10: 6 | C10: PIR & PVC Materials | D10: ='PIR and PVC Materials'!G12 -> 275358
B11: 7 | C11: Others | D11: =Others!C4 -> 0
C12: Grand Total | D12: =SUM(D5:D11) -> 30488419

Sheet Coil & Raw Materials
A1: Summary for Coils & Raw Materials
A2: SL | B2: Description | C2: Total value
A3: 1 | B3: Packed GI Regular Coil | C3: =H39 -> 7419749.5
A4: 2 | B4: Slitted Packed & Open GI Coil | C4: =H61 -> 5144547.7
A5: 3 | B5: Regular 275 GSM Open GI Coil | C5: =H73 -> 1499671
A6: 4 | B6: Open Aluminium Coil | C6: =H82 -> 2399756
A7: 5 | B7: GI Sheets | C7: =H90 -> 88392.6
A8: 6 | B8: Spares | C8: =H102 -> 946198
A9: 7 | B9: VCD Material | C9: =H118 -> 393243
A10: 8 | B10: MS L- Angle and Threaded Rod | C10: =H163 -> 46190
A11: 9 | B11: Scrap | C11: =H170 -> 302500
B12: Total | C12: =SUM(C3:C11) -> 18240248
A15: Annexure
B17: Regular Packed & Open GI Coil
A18: Sl. No. | B18: Category | C18: Coil ID | D18: Guage | E18: UOM | F18: Qty | G18: Rate | H18: Sub Total | I18: CGST @9% | J18: SGST @ 9% | K18: Total | L18: Make | M18: Remarks
A19: 1 | B19: Packed GI coil | C19: TG5AFB5284 | D19: 26 | E19: KG | F19: 4765 | G19: 83.3 | H19: =F19*G19 -> 396924.5 | I19: =H19*9% -> 35723.205 | J19: =I19 -> 35723.205 | K19: =H19+I19+J19 -> 468370.91 | L19: JSW | M19: 1220 Width
A20: 2 | B20: Packed GI coil | C20: 25COUNZ2000 | D20: 26 | E20: KG | F20: 6424 | G20: 83.3 | H20: =F20*G20 -> 535119.2 | I20: =H20*9% -> 48160.728 | J20: =I20 -> 48160.728 | K20: =H20+I20+J20 -> 631440.66 | L20: JSW | M20: 1220 Width
A21: 3 | B21: Packed GI coil | C21: 262ARQ1000 | D21: 26 | E21: KG | F21: 6547 | G21: 83.3 | H21: =F21*G21 -> 545365.1 | I21: =H21*9% -> 49082.859 | J21: =I21 -> 49082.859 | K21: =H21+I21+J21 -> 643530.82 | M21: 1250 Width
A22: 4 | B22: Packed GI coil | C22: 262AJB1000 | D22: 26 | E22: KG | F22: 6390 | G22: 83.3 | H22: =F22*G22 -> 532287 | I22: =H22*9% -> 47905.83 | J22: =I22 -> 47905.83 | K22: =H22+I22+J22 -> 628098.66 | M22: 1250 Width
A23: 5 | B23: Packed GI coil | C23: 25A35T2000 | D23: 24 | E23: KG | F23: 5800 | G23: 81.25 | H23: =F23*G23 -> 471250 | I23: =H23*9% -> 42412.5 | J23: =I23 -> 42412.5 | K23: =H23+I23+J23 -> 556075 | M23: 1220 Width
A24: 6 | B24: Packed GI coil | C24: 25A60X2000 | D24: 24 | E24: KG | F24: 5680 | G24: 81.25 | H24: =F24*G24 -> 461500 | I24: =H24*9% -> 41535 | J24: =I24 -> 41535 | K24: =H24+I24+J24 -> 544570 | M24: 1220 Width
A25: 7 | B25: Packed GI coil | C25: 26107L1000 | D25: 24 | E25: KG | F25: 5391 | G25: 81.25 | H25: =F25*G25 -> 438018.75 | I25: =H25*9% -> 39421.688 | J25: =I25 -> 39421.688 | K25: =H25+I25+J25 -> 516862.12 | M25: 1220 Width
A26: 8 | B26: Packed GI coil | C26: 26111T1000 | D26: 22 | E26: KG | F26: 4655 | G26: 79.2 | H26: =F26*G26 -> 368676 | I26: =H26*9% -> 33180.84 | J26: =I26 -> 33180.84 | K26: =H26+I26+J26 -> 435037.68 | M26: 1220 Width
A27: 9 | B27: Packed GI coil | C27: 262ARW1000 | D27: 22 | E27: KG | F27: 5444 | G27: 79.2 | H27: =F27*G27 -> 431164.8 | I27: =H27*9% -> 38804.832 | J27: =I27 -> 38804.832 | K27: =H27+I27+J27 -> 508774.46 | M27: 1220 Width
A28: 10 | B28: Packed GI coil | C28: 25C2GG1000 | D28: 20 | E28: KG | F28: 6445 | G28: 81.6 | H28: =F28*G28 -> 525912 | I28: =H28*9% -> 47332.08 | J28: =I28 -> 47332.08 | K28: =H28+I28+J28 -> 620576.16 | M28: 1220 Width
A29: 11 | B29: Packed GI coil | C29: SG3AEB1329 | D29: 18 | E29: KG | F29: 5120 | G29: 81.6 | H29: =F29*G29 -> 417792 | I29: =H29*9% -> 37601.28 | J29: =I29 -> 37601.28 | K29: =H29+I29+J29 -> 492994.56 | M29: 1250 Width
A30: 12 | B30: Packed GI coil | C30: 26237P2000 | D30: 18 | E30: KG | F30: 4765 | G30: 81.6 | H30: =F30*G30 -> 388824 | I30: =H30*9% -> 34994.16 | J30: =I30 -> 34994.16 | K30: =H30+I30+J30 -> 458812.32 | M30: 1250 Width
A31: 13 | B31: Packed GI coil | D31: 24 | E31: KG | F31: 2765 | G31: 72.1 | H31: =F31*G31 -> 199356.5 | I31: =H31*9% -> 17942.085 | J31: =I31 -> 17942.085 | K31: =H31+I31+J31 -> 235240.67 | M31: 600 mm Width
A32: 14 | B32: Packed GI coil | D32: 24 | E32: KG | F32: 2765 | G32: 72.1 | H32: =F32*G32 -> 199356.5 | I32: =H32*9% -> 17942.085 | J32: =I32 -> 17942.085 | K32: =H32+I32+J32 -> 235240.67 | M32: 600 mm Width
A33: 15 | B33: Open Coil | C33: TG3AEB5437 | D33: 26 | E33: KG | F33: 5710 | G33: 83.3 | H33: =F33*G33 -> 475643 | I33: =H33*9% -> 42807.87 | J33: =I33 -> 42807.87 | K33: =H33+I33+J33 -> 561258.74 | M33: 250 mm
A34: 16 | B34: Open Coil | C34: 26235YZ000 | D34: 24 | E34: KG | F34: =4270-1371 -> 2899 | G34: 81.25 | H34: =F34*G34 -> 235543.75 | I34: =H34*9% -> 21198.938 | J34: =I34 -> 21198.938 | K34: =H34+I34+J34 -> 277941.62 | M34: 200 mm
A35: 17 | B35: Open Coil | C35: TG3AFA5675 | D35: 22 | E35: KG | F35: =4830-635 -> 4195 | G35: 79.2 | H35: =F35*G35 -> 332244 | I35: =H35*9% -> 29901.96 | J35: =I35 -> 29901.96 | K35: =H35+I35+J35 -> 392047.92 | M35: 220 mm
A36: 18 | B36: Open Coil | C36: 25C2GG1000(2) | D36: 20 | E36: KG | F36: =2502-503 -> 1999 | G36: 81.6 | H36: =F36*G36 -> 163118.4 | I36: =H36*9% -> 14680.656 | J36: =I36 -> 14680.656 | K36: =H36+I36+J36 -> 192479.71 | M36: 130 mm
A37: 19 | B37: Open Coil | C37: TG3AB5437 | D37: 18 | E37: KG | F37: =4000-860 -> 3140 | G37: 81.6 | H37: =F37*G37 -> 256224 | I37: =H37*9% -> 23060.16 | J37: =I37 -> 23060.16 | K37: =H37+I37+J37 -> 302344.32 | M37: 1250 Width (190 mm)
A38: 20 | B38: Open Coil | C38: 24B6QV1000 | D38: 24 | E38: KG | F38: 649 | G38: 70 | H38: =F38*G38 -> 45430 | I38: =H38*9% -> 4088.7 | J38: =I38 -> 4088.7 | K38: =H38+I38+J38 -> 53607.4 | L38: JSW | M38: 940 mm Width (50 mm)
D39: Total | F39: =SUM(F19:F38) -> 91548 | H39: =SUM(H19:H38) -> 7419749.5 | I39: =SUM(I19:I38) -> 667777.45 | J39: =SUM(J19:J38) -> 667777.45 | K39: =SUM(K19:K38) -> 8755304.4
B41: Slitted Packed & Open GI Coil
A42: Sl. No. | B42: Category | C42: Coil Width | D42: Guage | E42: UOM | F42: Qty | G42: Rate | H42: Sub Total | I42: CGST @9% | J42: SGST @ 9% | K42: Total | L42: Make | M42: Remark
A43: 1 | B43: Packed/Open GI coil | C43: SLITTED COIL 137mm | D43: 26 | E43: KG | F43: =534+450 -> 984 | G43: 75.5 | H43: =F43*G43 -> 74292 | I43: =H43*9% -> 6686.28 | J43: =I43 -> 6686.28 | K43: =H43+I43+J43 -> 87664.56 | L43: JSW | M43: 120 GSM
A44: 2 | B44: Packed/Open GI coil | C44: SLITTED COIL 137mm | D44: 24 | E44: KG | F44: =(559*10)+(605*6)+600+400+143+65+60+40 -> 10528 | G44: 73.1 | H44: =F44*G44 -> 769596.8 | I44: =H44*9% -> 69263.712 | J44: =I44 -> 69263.712 | K44: =H44+I44+J44 -> 908124.22 | L44: JSW | M44: 120 GSM
...

Sheet Insulation
A2: Summary of Insulation Materials
A3: SL | B3: Description | C3: Total value
A4: 1 | B4: K Flex Insulation | C4: =F29 -> 2123498.4
A5: 2 | B5: Orient Thermobreak Insulation | C5: =F39 -> 508799
A6: 3 | B6: Supreme Insulation | C6: =F53 -> 3782727.6
A7: 4 | B7: Armaflex Insulation | C7: =F61 -> 546022
A8: 5 | B8: Armasound Insulaion | C8: =F68 -> 1207671
A9: 6 | B9: Aerocell Insulation | C9: =F74 -> 403740
A10: 7 | B10: Paramount Insulation | C10: =F80 -> 67875
A11: 8 | B11: Packing and wrapping Materials | C11: =F86 -> 42694.5
B12: Total | C12: =SUM(C4:C11) -> 8683027.5
A16: 1 | B16: K Flex Insulation
A17: SL | B17: DESCRIPTIONS | C17: TYPE OF INSULATION | D17: Stock QTY in SQMT | E17: Rate | F17: Sub Total | G17: CGST @9% | H17: SGST @ 9% | I17: Amount | J17: Remarks
A18: 1 | B18: Thermal | C18: 9mm | D18: 2520 | E18: 107 | F18: =D18*E18 -> 269640 | G18: =F18*9% -> 24267.6 | H18: =G18 -> 24267.6 | I18: =F18+G18+H18 -> 318175.2 | J18: 105 Roll
A19: 2 | B19: Thermal | C19: 13mm | D19: 436.8 | E19: 160 | F19: =D19*E19 -> 69888 | G19: =F19*9% -> 6289.92 | H19: =G19 -> 6289.92 | I19: =F19+G19+H19 -> 82467.84 | J19: 23 Roll
A20: 3 | B20: Thermal AM | C20: 13mm | D20: =16.8*3 -> 50.4 | E20: 200 | F20: =D20*E20 -> 10080 | G20: =F20*9% -> 907.2 | H20: =G20 -> 907.2 | I20: =F20+G20+H20 -> 11894.4 | J20: 3 Roll
A21: 4 | B21: Thermal | C21: 25MM | D21: 28.8 | E21: 315 | F21: =D21*E21 -> 9072 | G21: =F21*9% -> 816.48 | H21: =G21 -> 816.48 | I21: =F21+G21+H21 -> 10704.96 | J21: 3 Roll
A22: 5 | B22: Thermal ( Al. Foil ) | C22: 13mm | D22: 2335.2 | E22: 202 | F22: =D22*E22 -> 471710.4 | G22: =F22*9% -> 42453.936 | H22: =G22 -> 42453.936 | I22: =F22+G22+H22 -> 556618.27 | J22: 139 Roll
A23: 6 | B23: Thermal ( Al. Foil ) | C23: 19mm | D23: 1752 | E23: 290 | F23: =D23*E23 -> 508080 | G23: =F23*9% -> 45727.2 | H23: =G23 -> 45727.2 | I23: =F23+G23+H23 -> 599534.4
A24: 7 | B24: Thermal ( Al. Foil ) | C24: 25mm | D24: 32 | E24: 425 | F24: =D24*E24 -> 13600 | G24: =F24*9% -> 1224 | H24: =G24 -> 1224 | I24: =F24+G24+H24 -> 16048
A25: 8 | B25: Thermal ( IC-Clad Black ) AM | C25: 19mm | D25: 756 | E25: 463 | F25: =D25*E25 -> 350028 | G25: =F25*9% -> 31502.52 | H25: =G25 -> 31502.52 | I25: =F25+G25+H25 -> 413033.04 | J25: 63 Roll
A26: 9 | B26: Thermal Tape | C26: 3mm | D26: 50 | E26: 140 | F26: =600*E26 -> 84000 | G26: =F26*9% -> 7560 | H26: =G26 -> 7560 | I26: =F26+G26+H26 -> 99120
A27: 11 | B27: Acoustic | C27: 10mm | D27: 0 | E27: 375 | F27: =D27*E27 -> 0 | G27: =F27*9% -> 0 | H27: =G27 -> 0 | I27: =F27+G27+H27 -> 0
A28: 12 | B28: Acoustic | C28: 25mm | D28: 280 | E28: 1205 | F28: =D28*E28 -> 337400 | G28: =F28*9% -> 30366 | H28: =G28 -> 30366 | I28: =F28+G28+H28 -> 398132 | J28: 35 Box
F29: =SUM(F18:F28) -> 2123498.4 | G29: =SUM(G18:G28) -> 191114.86 | H29: =SUM(H18:H28) -> 191114.86 | I29: =SUM(I18:I28) -> 2505728.1
A31: 2 | B31: Thermobreak Insulation
A32: SL | B32: DESCRIPTIONS | C32: TYPE OF INSULATION | D32: Stock QTY in SQMT | E32: Rate | F32: Sub Total | G32: CGST @9% | H32: SGST @ 9% | I32: Amount | J32: Remarks
A33: 2 | B33: Thermal ( Al. Foil ) | C33: 9mm | D33: 120 | E33: 330 | F33: =D33*E33 -> 39600 | G33: =F33*9% -> 3564 | H33: =G33 -> 3564 | I33: =F33+G33+H33 -> 46728 | J33: 2 Roll
A34: 3 | B34: Thermal ( Al. Foil ) | C34: 19mm | D34: 72 | E34: 520 | F34: =D34*E34 -> 37440 | G34: =F34*9% -> 3369.6 | H34: =G34 -> 3369.6 | I34: =F34+G34+H34 -> 44179.2 | J34: 3 Roll
A35: 4 | B35: Acoustic ( Al. Foil ) | C35: 10mm | D35: 264 | E35: 560 | F35: =D35*E35 -> 147840 | G35: =F35*9% -> 13305.6 | H35: =G35 -> 13305.6 | I35: =F35+G35+H35 -> 174451.2 | J35: 11
A36: 5 | B36: Acoustic ( Al. Foil ) | C36: 15mm | D36: 289.8 | E36: 655 | F36: =D36*E36 -> 189819 | G36: =F36*9% -> 17083.71 | H36: =G36 -> 17083.71 | I36: =F36+G36+H36 -> 223986.42 | J36: 105
A37: 6 | B37: Acoustic ( Al. Foil ) | C37: 24mm | D37: 110.4 | E37: 750 | F37: =D37*E37 -> 82800 | G37: =F37*9% -> 7452 | H37: =G37 -> 7452 | I37: =F37+G37+H37 -> 97704 | J37: 40
A38: 7 | B38: Aluminium Tape | D38: 20 | E38: 565 | F38: =D38*E38 -> 11300 | G38: =F38*9% -> 1017 | H38: =G38 -> 1017 | I38: =F38+G38+H38 -> 13334
F39: =SUM(F33:F38) -> 508799 | G39: =SUM(G33:G38) -> 45791.91 | H39: =SUM(H33:H38) -> 45791.91 | I39: =SUM(I33:I38) -> 600382.82
A41: 3 | B41: Supreme Insulation
A42: SL | B42: DESCRIPTIONS | C42: TYPE OF INSULATION | D42: Stock QTY in SQMT | E42: Rate | F42: Sub Total | G42: CGST @9% | H42: SGST @ 9% | I42: Amount | J42: Remarks
A43: 1 | B43: Thermal ( Flange - 150mm Slit ) | C43: 9mm | D43: 1608 | E43: 154 | F43: =D43*E43 -> 247632 | G43: =F43*9% -> 22286.88 | H43: =F43*9% -> 22286.88 | I43: =SUM(F43:H43) -> 292205.76 | J43: 67 Roll
A44: 2 | B44: Thermal | C44: 9mm | D44: 432 | E44: 101 | F44: =D44*E44 -> 43632 | G44: =F44*9% -> 3926.88 | H44: =F44*9% -> 3926.88 | I44: =SUM(F44:H44) -> 51485.76 | J44: 18 Roll
A45: 3 | B45: Thermal ( 1100mm Width ) | C45: 13mm | D45: 184.8 | E45: 162 | F45: =D45*E45 -> 29937.6 | G45: =F45*9% -> 2694.384 | H45: =G45 -> 2694.384 | I45: =F45+G45+H45 -> 35326.368 | J45: 11 Roll
A46: 4 | B46: Thermal ( Al. Foil )- Nitrile Rubber | C46: 13mm | D46: 3830.4 | E46: 207 | F46: =D46*E46 -> 792892.8 | G46: =F46*9% -> 71360.352 | H46: =G46 -> 71360.352 | I46: =F46+G46+H46 -> 935613.5 | J46: 228 Roll
...

Sheet Finished Goods
A2: Summary for Finshed and Semi finished Goods
A3: SL | B3: Description | C3: Total value
A4: 1 | B4: Finished Goods for KNND | C4: =G45 -> 2701224
A5: 2 | B5: Semi Finished for KNND | C5: =G51 -> 17864
B6: Total | C6: =SUM(C4:C5) -> 2719088
A10: Finished Goods As on 31.03.26
A11: Sl | B11: Party Name | C11: Site Name | D11: Description | E11: Qty | F11: Rate | G11: Value | H11: CGST | I11: SGST | J11: Total | K11: Remarks | L11: Insulation
A12: 1 | B12: KNND Associates Pvt Ltd | C12: TCS Noida SDB-2 Second Floor Ahu-1&2 to 7&8 oval duct | D12: 24G SPIRAL OVAL DUCT WITH 9 MM THERMAL | E12: 2.5 | F12: =680+252 -> 932 | G12: =E12*F12 -> 2330 | H12: =G12*9% -> 209.7 | I12: =G12*9% -> 209.7 | J12: =G12+H12+I12 -> 2749.4 | K12: Material Ready to dispatch | L12: Completed
D13: 22G SPIRAL OVAL DUCT WITH 9 MM THERMAL | E13: =2.3+2.8+2.1+2.7+3.1+3.1 -> 16.1 | F13: =795+252 -> 1047 | G13: =E13*F13 -> 16856.7 | H13: =G13*9% -> 1517.103 | I13: =G13*9% -> 1517.103 | J13: =G13+H13+I13 -> 19890.906
D14: 20G SPIRAL OVAL DUCT WITH 9 MM THERMAL | E14: =4.3+3.6 -> 7.9 | F14: =950+252 -> 1202 | G14: =E14*F14 -> 9495.8 | H14: =G14*9% -> 854.622 | I14: =G14*9% -> 854.622 | J14: =G14+H14+I14 -> 11205.044
D15: 20g Oval VCd | E15: 19.5 | F15: 3300 | G15: =E15*F15 -> 64350 | H15: =G15*9% -> 5791.5 | I15: =G15*9% -> 5791.5 | J15: =G15+H15+I15 -> 75933
A16: 3 | B16: KNND Associates Pvt Ltd | C16: GDGM Hospital Raipur First Floor part-2 | D16: 24G TDF PLAIN DUCT (L-TYPE ) | E16: 54.1 | F16: 525 | G16: =E16*F16 -> 28402.5 | H16: =G16*9% -> 2556.225 | I16: =G16*9% -> 2556.225 | J16: =G16+H16+I16 -> 33514.95
D17: 26G TDF PLAIN DUCT (L-TYPE ) | E17: 799.2 | F17: 475 | G17: =E17*F17 -> 379620 | H17: =G17*9% -> 34165.8 | I17: =G17*9% -> 34165.8 | J17: =G17+H17+I17 -> 447951.6
D18: 22G TDF PLAIN DUCT (L-TYPE ) | E18: 61.1 | F18: 685 | G18: =E18*F18 -> 41853.5 | H18: =G18*9% -> 3766.815 | I18: =G18*9% -> 3766.815 | J18: =G18+H18+I18 -> 49387.13
A19: 4 | B19: Lakshmi Fabrication | C19: Lenovo Bangalore 5th floor Oval duct | D19: 24G TDF PLAIN DUCT | E19: 18.4 | F19: 585 | G19: =E19*F19 -> 10764 | H19: =G19*9% -> 968.76 | I19: =G19*9% -> 968.76 | J19: =G19+H19+I19 -> 12701.52 | K19: Wip | L19: Wip
D20: 24G TDF with 19mm Thermal Insu ( GC Cloth ) | E20: =209+122.7+4.4 -> 336.1 | F20: 585 | G20: =E20*F20 -> 196618.5 | H20: =G20*9% -> 17695.665 | I20: =G20*9% -> 17695.665 | J20: =G20+H20+I20 -> 232009.83
D21: 24G TDF with 10mm Acou. | E21: 57.8 | F21: 585 | G21: =E21*F21 -> 33813 | H21: =G21*9% -> 3043.17 | I21: =G21*9% -> 3043.17 | J21: =G21+H21+I21 -> 39899.34
D22: 24G TDF with 25mm Acou. | E22: =9.9+0.6 -> 10.5 | F22: 585 | G22: =E22*F22 -> 6142.5 | H22: =G22*9% -> 552.825 | I22: =G22*9% -> 552.825 | J22: =G22+H22+I22 -> 7248.15
D23: 24G Spiral Oval Duct with 13mm Thermal Insu | E23: 14.7 | F23: =660+380 -> 1040 | G23: =E23*F23 -> 15288 | H23: =G23*9% -> 1375.92 | I23: =G23*9% -> 1375.92 | J23: =G23+H23+I23 -> 18039.84
D24: 22G Spiral Oval Duct with 13mm Thermal Insu | E24: =10.3+13.2 -> 23.5 | F24: =795+380 -> 1175 | G24: =E24*F24 -> 27612.5 | H24: =G24*9% -> 2485.125 | I24: =G24*9% -> 2485.125 | J24: =G24+H24+I24 -> 32582.75
D25: 22G TDF with 19mm Thermal Insu ( GC Cloth ) | E25: =39.5+22.9 -> 62.4 | F25: 790 | G25: =E25*F25 -> 49296 | H25: =G25*9% -> 4436.64 | I25: =G25*9% -> 4436.64 | J25: =G25+H25+I25 -> 58169.28
D26: 22G TDF with 10mm Acou. | E26: 6.1 | F26: 790 | G26: =E26*F26 -> 4819 | H26: =G26*9% -> 433.71 | I26: =G26*9% -> 433.71 | J26: =G26+H26+I26 -> 5686.42
D27: 22G TDF with 25mm Acou. | E27: 13.1 | F27: 790 | G27: =E27*F27 -> 10349 | H27: =G27*9% -> 931.41 | I27: =G27*9% -> 931.41 | J27: =G27+H27+I27 -> 12211.82
D28: 20G TDF with 19mm Thermal Insu ( GC Cloth ) | E28: =86.4+40.1 -> 126.5 | F28: 915 | G28: =E28*F28 -> 115747.5 | H28: =G28*9% -> 10417.275 | I28: =G28*9% -> 10417.275 | J28: =G28+H28+I28 -> 136582.05
D29: 20G TDF with 25mm Acou. | E29: 6.1 | F29: 915 | G29: =E29*F29 -> 5581.5 | H29: =G29*9% -> 502.335 | I29: =G29*9% -> 502.335 | J29: =G29+H29+I29 -> 6586.17
D30: 18G TDF with 19mm Thermal Insu ( GC Cloth ) | E30: =15.8+25.8 -> 41.6 | F30: 1030 | G30: =E30*F30 -> 42848 | H30: =G30*9% -> 3856.32 | I30: =G30*9% -> 3856.32 | J30: =G30+H30+I30 -> 50560.64
D31: 18G TTDF with 25mm Acou. | E31: =29.4+28.1 -> 57.5 | F31: 1030 | G31: =E31*F31 -> 59225 | H31: =G31*9% -> 5330.25 | I31: =G31*9% -> 5330.25 | J31: =G31+H31+I31 -> 69885.5
A32: 5 | B32: KNND Associates Pvt Ltd | C32: BlackStone 6th Floor AHU-1 & AHU-2 | D32: 24G Plain Duct | E32: =9.7+45.7 -> 55.4 | F32: 585 | G32: =E32*F32 -> 32409 | H32: =G32*9% -> 2916.81 | I32: =G32*9% -> 2916.81 | J32: =G32+H32+I32 -> 38242.62 | K32: Ahu-1 complete / ahu-2 Wip | L32: Wip
D33: 24G TDF with 9mm Thermal Insu | E33: =121.9+206.2 -> 328.1 | F33: =585+289 -> 874 | G33: =E33*F33 -> 286759.4 | H33: =G33*9% -> 25808.346 | I33: =G33*9% -> 25808.346 | J33: =G33+H33+I33 -> 338376.09
D34: 24G TDF with 15mm Acou. | E34: =22.3+36.9 -> 59.2 | F34: =585+805 -> 1390 | G34: =E34*F34 -> 82288 | H34: =G34*9% -> 7405.92 | I34: =G34*9% -> 7405.92 | J34: =G34+H34+I34 -> 97099.84
D35: 24G TDF with 25mm Acou. | E35: =2+18.9 -> 20.9 | F35: =585+1271 -> 1856 | G35: =E35*F35 -> 38790.4 | H35: =G35*9% -> 3491.136 | I35: =G35*9% -> 3491.136 | J35: =G35+H35+I35 -> 45772.672
D36: 22G TDF with 9mm Thermal Insu | E36: =44.7+41.8 -> 86.5 | F36: =790+289 -> 1079 | G36: =E36*F36 -> 93333.5 | H36: =G36*9% -> 8400.015 | I36: =G36*9% -> 8400.015 | J36: =G36+H36+I36 -> 110133.53
D37: 22G TDF with 25mm Acou. | E37: =49.3+35.2 -> 84.5 | F37: =790+1271 -> 2061 | G37: =E37*F37 -> 174154.5 | H37: =G37*9% -> 15673.905 | I37: =G37*9% -> 15673.905 | J37: =G37+H37+I37 -> 205502.31
D38: 20G TDF with 25mm Acou. | E38: 14.7 | F38: =915+1271 -> 2186 | G38: =E38*F38 -> 32134.2 | H38: =G38*9% -> 2892.078 | I38: =G38*9% -> 2892.078 | J38: =G38+H38+I38 -> 37918.356
A39: 8 | B39: KNND Associates Pvt Ltd | C39: Market Of India chennai Ground Floor Part-1 & Part-2 | D39: 24g TDF with 13mm Thermal Insu | E39: =404.6 -> 404.6 | F39: =565+330 -> 895 | G39: =E39*F39 -> 362117 | H39: =G39*9% -> 32590.53 | I39: =G39*9% -> 32590.53 | J39: =G39+H39+I39 -> 427298.06 | K39: Production Completed | L39: Completed | M39: Completed
D40: 24G TDF TDF with 15mm Acoustic | E40: 50.1 | F40: =565+850 -> 1415 | G40: =E40*F40 -> 70891.5 | H40: =G40*9% -> 6380.235 | I40: =G40*9% -> 6380.235 | J40: =G40+H40+I40 -> 83651.97
D41: 24G Plain duct | E41: 227.9 | F41: 565 | G41: =E41*F41 -> 128763.5 | H41: =G41*9% -> 11588.715 | I41: =G41*9% -> 11588.715 | J41: =G41+H41+I41 -> 151940.93
D42: 150mm Dia Butterfly Damper In Nos | E42: 171 | F42: 350 | G42: =E42*F42 -> 59850 | H42: =G42*9% -> 5386.5 | I42: =G42*9% -> 5386.5 | J42: =G42+H42+I42 -> 70623
D43: 200mm Dia Butterfly Damper In Nos | E43: 326 | F43: 400 | G43: =E43*F43 -> 130400 | H43: =G43*9% -> 11736 | I43: =G43*9% -> 11736 | J43: =G43+H43+I43 -> 153872
D44: 250mm Dia Butterfly Damper In Nos | E44: 192 | F44: 460 | G44: =E44*F44 -> 88320 | H44: =G44*9% -> 7948.8 | I44: =G44*9% -> 7948.8 | J44: =G44+H44+I44 -> 104217.6
...

Sheet Consumables 
A2: CONSUMABLE ITEMS
A3: Sl No | B3: Discription | C3: Make | D3: Qty | E3: UOM | F3: Rate/Unit (Rs) | G3: Total Value | H3: CGST | I3: SGST | J3: Total
A4: 1 | B4: Drilling Bit (8MM) | D4: 10 | E4: BOX | F4: 206 | G4: =D4*F4 -> 2060 | H4: =G4*9% -> 185.4 | I4: =H4 -> 185.4 | J4: =G4+H4+I4 -> 2430.8
A5: 2 | B5: Drilling Bit (8.2MM) | D5: 6 | E5: BOX | F5: 232 | G5: =D5*F5 -> 1392 | H5: =G5*9% -> 125.28 | I5: =H5 -> 125.28 | J5: =G5+H5+I5 -> 1642.56
A6: 3 | B6: Drilling Bit (10MM) | D6: 10 | E6: BOX | F6: 411 | G6: =D6*F6 -> 4110 | H6: =G6*9% -> 369.9 | I6: =H6 -> 369.9 | J6: =G6+H6+I6 -> 4849.8
A7: 4 | B7: Drilling Bit (12MM) | D7: 25 | E7: NOS | F7: 598 | G7: =D7*F7 -> 14950 | H7: =G7*9% -> 1345.5 | I7: =H7 -> 1345.5 | J7: =G7+H7+I7 -> 17641
A8: 5 | B8: Drilling Bit (3.5MM) | D8: 2 | E8: Box | F8: 45 | G8: =D8*F8 -> 90 | H8: =G8*9% -> 8.1 | I8: =H8 -> 8.1 | J8: =G8+H8+I8 -> 106.2
A9: 6 | B9: Drilling Bit (05MM) | D9: 5 | E9: Box | F9: 148 | G9: =D9*F9 -> 740 | H9: =G9*9% -> 66.6 | I9: =H9 -> 66.6 | J9: =G9+H9+I9 -> 873.2
A10: 7 | B10: Drilling Bit (06MM) | D10: 5 | E10: Box | F10: 165 | G10: =D10*F10 -> 825 | H10: =G10*9% -> 74.25 | I10: =H10 -> 74.25 | J10: =G10+H10+I10 -> 973.5
A11: 8 | B11: Scissors | C11: Stanley | D11: 3 | E11: NOS | F11: 682 | G11: =D11*F11 -> 2046 | H11: =G11*9% -> 184.14 | I11: =H11 -> 184.14 | J11: =G11+H11+I11 -> 2414.28
A12: 9 | B12: Ear plug (8.90 Rs per one) | D12: 3 | E12: Box | F12: 4450 | G12: =D12*F12 -> 13350 | H12: =G12*9% -> 1201.5 | I12: =H12 -> 1201.5 | J12: =G12+H12+I12 -> 15753
A13: 10 | B13: Digital Clamp Meter | D13: 3 | E13: NOS | F13: 800 | G13: =D13*F13 -> 2400 | H13: =G13*9% -> 216 | I13: =H13 -> 216 | J13: =G13+H13+I13 -> 2832
A14: 11 | B14: Stanley Tester | D14: 8 | E14: NOS | F14: 70 | G14: =D14*F14 -> 560 | H14: =G14*9% -> 50.4 | I14: =H14 -> 50.4 | J14: =G14+H14+I14 -> 660.8
A15: 12 | B15: Spray Paint Gun Type 59 | D15: 2 | E15: NOS | F15: 1250 | G15: =D15*F15 -> 2500 | H15: =G15*9% -> 225 | I15: =H15 -> 225 | J15: =G15+H15+I15 -> 2950
A16: 13 | B16: Measurement Tape 5mm (19mm) | C16: Freemans | D16: 34 | E16: NOS | F16: 110 | G16: =D16*F16 -> 3740 | H16: =G16*9% -> 336.6 | I16: =H16 -> 336.6 | J16: =G16+H16+I16 -> 4413.2
A17: 14 | B17: Measurement Tape 7.5mm | D17: 13 | E17: NOS | F17: 230 | G17: =D17*F17 -> 2990 | H17: =G17*9% -> 269.1 | I17: =H17 -> 269.1 | J17: =G17+H17+I17 -> 3528.2
A18: 15 | B18: Marker (Bold - E) | D18: 22 | E18: NOS | F18: 20 | G18: =D18*F18 -> 440 | H18: =G18*9% -> 39.6 | I18: =H18 -> 39.6 | J18: =G18+H18+I18 -> 519.2
A19: 16 | B19: Marker (Fine Tip) | D19: 31 | E19: NOS | F19: 10 | G19: =D19*F19 -> 310 | H19: =G19*9% -> 27.9 | I19: =H19 -> 27.9 | J19: =G19+H19+I19 -> 365.8
A20: 17 | B20: Adjustable Spanner | C20: Taparia | D20: 5 | E20: NOS | F20: 411 | G20: =D20*F20 -> 2055 | H20: =G20*9% -> 184.95 | I20: =H20 -> 184.95 | J20: =G20+H20+I20 -> 2424.9
A21: 18 | B21: Ring Spanner Set | C21: Taparia | D21: 4 | E21: SET | F21: 1463 | G21: =D21*F21 -> 5852 | H21: =G21*9% -> 526.68 | I21: =H21 -> 526.68 | J21: =G21+H21+I21 -> 6905.36
A22: 19 | B22: Hammer with handle Ball Pein(WH500B) | C22: Taparia | D22: 6 | E22: NOS | F22: 250 | G22: =D22*F22 -> 1500 | H22: =G22*9% -> 135 | I22: =H22 -> 135 | J22: =G22+H22+I22 -> 1770
A23: 20 | B23: Opne Jaw Spanner Set | C23: Taparia | D23: 4 | E23: SET | F23: 690 | G23: =D23*F23 -> 2760 | H23: =G23*9% -> 248.4 | I23: =H23 -> 248.4 | J23: =G23+H23+I23 -> 3256.8
A24: 21 | B24: Screw Drivers (Size 8*300mm) | C24: Taparia | D24: 1 | E24: SET | F24: 166 | G24: =D24*F24 -> 166 | H24: =G24*9% -> 14.94 | I24: =H24 -> 14.94 | J24: =G24+H24+I24 -> 195.88
A25: 22 | B25: Hacksaw Blades (300*25) 50 Nos Each (2 Box) | C25: Taparia | D25: 100 | E25: NOS | F25: 25 | G25: =D25*F25 -> 2500 | H25: =G25*9% -> 225 | I25: =H25 -> 225 | J25: =G25+H25+I25 -> 2950
A26: 23 | B26: Flat Files | D26: 3 | E26: NOS | F26: 290 | G26: =D26*F26 -> 870 | H26: =G26*9% -> 78.3 | I26: =H26 -> 78.3 | J26: =G26+H26+I26 -> 1026.6
A27: 24 | B27: Socket Set (12.7mm Drive) | C27: Taparia | D27: 1 | E27: SET | F27: 1800 | G27: =D27*F27 -> 1800 | H27: =G27*9% -> 162 | I27: =H27 -> 162 | J27: =G27+H27+I27 -> 2124
A28: 25 | B28: 16mm Allen Key | C28: Jetech | D28: 3 | E28: NOS | F28: 765 | G28: =D28*F28 -> 2295 | H28: =G28*9% -> 206.55 | I28: =H28 -> 206.55 | J28: =G28+H28+I28 -> 2708.1
A29: 26 | B29: 12mm Allen Key | C29: Jetech | D29: 3 | E29: NOS | F29: 765 | G29: =D29*F29 -> 2295 | H29: =G29*9% -> 206.55 | I29: =H29 -> 206.55 | J29: =G29+H29+I29 -> 2708.1
A30: 27 | B30: Digimatic Micrometer | C30: Mitutoyo | D30: 1 | E30: NOS | F30: 4520 | G30: =D30*F30 -> 4520 | H30: =G30*9% -> 406.8 | I30: =H30 -> 406.8 | J30: =G30+H30+I30 -> 5333.6
A31: 28 | B31: Ball Pein Hammer with Handle (WH800B) | C31: Taparia | D31: 6 | E31: NOS | F31: 260 | G31: =D31*F31 -> 1560 | H31: =G31*9% -> 140.4 | I31: =H31 -> 140.4 | J31: =G31+H31+I31 -> 1840.8
A32: 29 | B32: Paint Flat Brush 14 (20 Each) 3 Packet | D32: 60 | E32: NOS | F32: 80 | G32: =D32*F32 -> 4800 | H32: =G32*9% -> 432 | I32: =H32 -> 432 | J32: =G32+H32+I32 -> 5664
A33: 30 | B33: Paint Brush 1" (2 Box) 12 Each | D33: 24 | E33: NOS | F33: 20 | G33: =D33*F33 -> 480 | H33: =G33*9% -> 43.2 | I33: =H33 -> 43.2 | J33: =G33+H33+I33 -> 566.4
A34: 31 | B34: Paint Brush 2" (1 Box) 12 Each | D34: 12 | E34: NOS | F34: 280 | G34: =D34*F34 -> 3360 | H34: =G34*9% -> 302.4 | I34: =H34 -> 302.4 | J34: =G34+H34+I34 -> 3964.8
A35: 32 | B35: Electric Cable Ties (ET250*4.8) | D35: 3 | E35: Pocket | F35: 185 | G35: =D35*F35 -> 555 | H35: =G35*9% -> 49.95 | I35: =H35 -> 49.95 | J35: =G35+H35+I35 -> 654.9
A36: 33 | B36: Electric Cable Ties (ET200*3.8) | D36: 6 | E36: Pocket | F36: 185 | G36: =D36*F36 -> 1110 | H36: =G36*9% -> 99.9 | I36: =H36 -> 99.9 | J36: =G36+H36+I36 -> 1309.8
A37: 34 | B37: Electric Cable Ties (ET300*4.8) | D37: 4 | E37: Pocket | F37: 185 | G37: =D37*F37 -> 740 | H37: =G37*9% -> 66.6 | I37: =H37 -> 66.6 | J37: =G37+H37+I37 -> 873.2
A38: 35 | B38: GE- Lock Tie Closure (250*3.2) | D38: 7 | E38: Pocket | F38: 185 | G38: =D38*F38 -> 1295 | H38: =G38*9% -> 116.55 | I38: =H38 -> 116.55 | J38: =G38+H38+I38 -> 1528.1
A39: 36 | B39: Electric Cable Tie (ET150x3.6) | D39: 6 | E39: Pocket | F39: 185 | G39: =D39*F39 -> 1110 | H39: =G39*9% -> 99.9 | I39: =H39 -> 99.9 | J39: =G39+H39+I39 -> 1309.8
A40: 37 | B40: Electric Cable Tie (2.2x100mm) | D40: 6 | E40: Pocket | F40: 185 | G40: =D40*F40 -> 1110 | H40: =G40*9% -> 99.9 | I40: =H40 -> 99.9 | J40: =G40+H40+I40 -> 1309.8
A41: 38 | B41: Round files | D41: 4 | E41: NOS | F41: 150 | G41: =D41*F41 -> 600 | H41: =G41*9% -> 54 | I41: =H41 -> 54 | J41: =G41+H41+I41 -> 708
...

Sheet Tools & Electrical
A1: Tools & Electrical Items
B2: Description | C2: Sub Total | D2: Cgst 9% | E2: Sgst 9% | F2: Total value
A3: 1 | B3: Tools | C3: =G25 -> 145148 | D3: =C3*9% -> 13063.32 | E3: =C3*9% -> 13063.32 | F3: =C3+D3+E3 -> 171274.64
A4: 2 | B4: Electrical | C4: =N20 -> 0 | D4: =C4*9% -> 0 | E4: =C4*9% -> 0 | F4: =C4+D4+E4 -> 0
B5: Total | C5: =SUM(C3:C4) -> 145148 | D5: =SUM(D3:D4) -> 13063.32 | E5: =SUM(E3:E4) -> 13063.32 | F5: =SUM(F3:F4) -> 171274.64
A8: TOOLS | I8: Electrical Material
A9: Sl No | B9: Discription | C9: Make | D9: Qty | E9: UOM | F9: Rate/Unit (Rs) | G9: Total Value | I9: Sl No | J9: Discription | K9: Qty | L9: UOM | M9: Rate/Unit (Rs) | N9: Total Value
A10: 1 | B10: Cutting Plier | D10: 2 | E10: NOS | F10: 215 | G10: =D10*F10 -> 430 | N10: =K10*M10 -> 0
A11: 2 | B11: Pipe Rinch | C11: Taparia | D11: 1 | E11: NOS | F11: 585 | G11: =D11*F11 -> 585 | N11: =K11*M11 -> 0
A12: 3 | B12: Angle Grinder 100mm | C12: Makita | D12: 4 | E12: NOS | F12: 1652 | G12: =D12*F12 -> 6608 | N12: =K12*M12 -> 0
A13: 4 | B13: Hammaring Drilling Machine 16mm (5/8) | C13: Makita | D13: 8 | E13: NOS | F13: 6589 | G13: =D13*F13 -> 52712 | N13: =K13*M13 -> 0
A14: 5 | B14: Hammer with handle | C14: Taparia | D14: 6 | E14: NOS | F14: 190 | G14: =D14*F14 -> 1140 | N14: =K14*M14 -> 0
A15: 6 | B15: Ball Pein Hammer with Handle | C15: Taparia | D15: 38 | E15: NOS | F15: 250 | G15: =D15*F15 -> 9500 | N15: =K15*M15 -> 0
A16: 7 | B16: Air Hydraulic Rivit Gun (4.8mm) | C16: Sumake | D16: 5 | E16: NOS | F16: 6250 | G16: =D16*F16 -> 31250 | N16: =K16*M16 -> 0
A17: 8 | B17: Carbon Dioxide Regulator | C17: Yamato | D17: 5 | E17: NOS | F17: 1350 | G17: =D17*F17 -> 6750 | N17: =K17*M17 -> 0
A18: 9 | B18: Soldring Gun | D18: 2 | E18: NOS | F18: 710 | G18: =D18*F18 -> 1420 | N18: =K18*M18 -> 0
A19: 10 | B19: Nose plier (Long Nose)/Taparia | C19: Taparia | D19: 5 | E19: NOS | F19: 177 | G19: =D19*F19 -> 885 | N19: =K19*M19 -> 0
A20: 11 | B20: Nose plier (Straight) /Taparia | C20: Taparia | D20: 6 | E20: NOS | F20: 233 | G20: =D20*F20 -> 1398 | I20: Total | N20: =SUM(N10:N19) -> 0
A21: 12 | B21: Makita Heat Gun (HG6530V-HG6531C) | C21: Makita | D21: 2 | E21: NOS | F21: 8300 | G21: =D21*F21 -> 16600
A22: 13 | B22: Tin Snip Straight Cutter | C22: Dayton | D22: 10 | E22: NOS | F22: 690 | G22: =D22*F22 -> 6900
A23: 14 | B23: Snip Straight Cutter | C23: Jetech | D23: 5 | E23: NOS | F23: 690 | G23: =D23*F23 -> 3450
A24: 15 | B24: Pin Sheet Cutter (snips) | C24: Stanley Fatmax | D24: 8 | E24: NOS | F24: 690 | G24: =D24*F24 -> 5520
B25: Total | F25: =SUM(F10:F24) -> 28571 | G25: =SUM(G10:G24) -> 145148

Sheet PIR and PVC Materials
B4: PIR and PVC Materials
A5: SL | B5: Discription | C5: Type | D5: UOM | E5: Stock QTY | F5: Rate | G5: Sub Total | H5: CGST @9% | I5: SGST @ 9% | J5: Amount | K5: Remarks
A6: 1 | B6: PIR SHEET (With Accessories) | C6: 20 mm | D6: Sqm | E6: =4.8*54 -> 259.2 | F6: 510 | G6: =E6*F6 -> 132192 | H6: =G6*9% -> 11897.28 | I6: =G6*9% -> 11897.28 | J6: =G6+H6+I6 -> 155986.56 | K6: 54 nos
A7: 2 | B7: PIR SHEET ( with Accessories) | C7: 30 mm | D7: Sqm | E7: 138.8 | F7: 545 | G7: =E7*F7 -> 75646 | H7: =G7*9% -> 6808.14 | I7: =G7*9% -> 6808.14 | J7: =G7+H7+I7 -> 89262.28 | K7: 28 nos
A8: 3 | B8: PIR PVC U CLEATS | C8: 20 mm | D8: Nos | E8: 60 | F8: 58 | G8: =E8*F8 -> 3480 | H8: =G8*9% -> 313.2 | I8: =G8*9% -> 313.2 | J8: =G8+H8+I8 -> 4106.4
A9: 4 | B9: PIR PVC H CLEATS | D9: Nos | E9: 240 | F9: 36 | G9: =E9*F9 -> 8640 | H9: =G9*9% -> 777.6 | I9: =G9*9% -> 777.6 | J9: =G9+H9+I9 -> 10195.2
A10: 5 | B10: GLASS WOOL | C10: 25 mm | D10: nos | E10: 70 | F10: 500 | G10: =E10*F10 -> 35000 | H10: =G10*9% -> 3150 | I10: =G10*9% -> 3150 | J10: =G10+H10+I10 -> 41300
A11: 6 | B11: GLASS WOOL | C11: 50 mm | D11: nos | E11: 34 | F11: 600 | G11: =E11*F11 -> 20400 | H11: =G11*9% -> 1836 | I11: =G11*9% -> 1836 | J11: =G11+H11+I11 -> 24072
B12: Total | G12: =SUM(G6:G11) -> 275358 | H12: =G12*9% -> 24782.22 | I12: =G12*9% -> 24782.22 | J12: =SUM(J6:J11) -> 324922.44
A14: SL | B14: Accessories | C14: Type | D14: UOM | E14: Stock QTY
A15: 1 | B15: PIR PVC F FLANGE | C15: 30 mm | D15: Nos | E15: 40
A16: 2 | B16: PIR PVC U FLANGE | C16: 30 mm | D16: Nos | E16: 160
A17: 3 | B17: PIR PVC F FLANGE | C17: 20 mm | D17: Nos | E17: 2
A18: 4 | B18: PIR PVC U FLANGE | C18: 20 mm | D18: Nos | E18: 18
A19: 5 | B19: PIR PVC DUCT SUPPORT | D19: Nos | E19: 80
A20: 6 | B20: PIR AlUMINIUM H FLANGE | C20: 20 mm | D20: Nos | E20: 30
A21: 7 | B21: PIR ALUMINIUM F FLANGE | C21: 20 mm | D21: Nos | E21: 60
A22: 8 | B22: PIR ALUMINIUM U FLANGE | C22: 20 mm | D22: Nos | E22: 10
A23: 9 | B23: PIR AlUMINIUM H FLANGE | C23: 30 mm | D23: Nos | E23: 5
A24: 10 | B24: PIR ALUMINIUM U FLANGE | C24: 30 mm | D24: Nos | E24: 5
A25: 11 | B25: PVC CLEATS | C25: 30 mm | D25: Nos | E25: 1300
A26: 12 | B26: PVC CLEATS | C26: 20 mm | D26: Nos | E26: 800
A27: 13 | B27: PVC CLEATS | C27: 30 mm | D27: Nos | E27: 710

Sheet Others
A1: Summary for Other Materials
B2: Description | C2: Total value
A3: 1 | B3: Other Materials | C3: =G11 -> 0
B4: Total | C4: =SUM(C3:C3) -> 0
B7: Other Materials
A8: SL | B8: Discription | C8: Type | D8: Unit | E8: Stock QTY | F8: Rate | G8: Value | H8: CGST @9% | I8: SGST @ 9% | J8: Total | K8: Remarks
A9: 1
A10: 2
B11: Total | G11: =SUM(G9:G10) -> 0 | H11: =SUM(H9:H10) -> 0 | I11: =SUM(I9:I10) -> 0 | J11: =SUM(J9:J10) -> 0
